Workbook
Name lstCustomers: CUSTOMERS!$A$5:INDEX(CUSTOMERS!$A$5:$A$2000,MAX(1,COUNTA(CUSTOMERS!$A$5:$A$2000)))
Name lstProducts: PRODUCTS!$A$5:INDEX(PRODUCTS!$A$5:$A$2000,MAX(1,COUNTA(PRODUCTS!$A$5:$A$2000)))
Name lstOrders: INVOICE!$K$16:INDEX(INVOICE!$K$16:$K$75,MAX(1,COUNTIF(INVOICE!$K$16:$K$75,"?*")))

Sheet DASHBOARD
A1: Happy Hatch – SALES & INVENTORY DASHBOARD | G1: LOGO (Insert Happy Hatch logo here)
A2: Change the yellow cells to search any date range. All figures below update automatically.
A3: From date | B3: 46266
A4: To date (inclusive) | B4: 46326
A5: Low-stock threshold (units) | B5: 20
A7: Sales (Net Amount) | C7: Units sold | E7: No. of sales entries | G7: Estimated revenue (profit)
A8: =SUMIFS(SALES!$I$5:$I$2000,SALES!$B$5:$B$2000,">="&$B$3,SALES!$B$5:$B$2000,"<="&$B$4) | C8: =SUMIFS(SALES!$H$5:$H$2000,SALES!$B$5:$B$2000,">="&$B$3,SALES!$B$5:$B$2000,"<="&$B$4) | E8: =COUNTIFS(SALES!$B$5:$B$2000,">="&$B$3,SALES!$B$5:$B$2000,"<="&$B$4) | G8: =SUMPRODUCT(SUMIFS(SALES!$H$5:$H$2000,SALES!$D$5:$D$2000,PRODUCTS!$A$5:$A$2000,SALES!$B$5:$B$2000,">="&$B$3,SALES!$B$5:$B$2000,"<="&$B$4)*PRODUCTS!$K$5:$K$2000)
A10: Purchase cost | C10: Units purchased | E10: Units in stock (now) | G10: Low-stock products
A11: =SUMIFS(PURCHASE!$G$5:$G$2000,PURCHASE!$B$5:$B$2000,">="&$B$3,PURCHASE!$B$5:$B$2000,"<="&$B$4) | C11: =SUMIFS(PURCHASE!$E$5:$E$2000,PURCHASE!$B$5:$B$2000,">="&$B$3,PURCHASE!$B$5:$B$2000,"<="&$B$4) | E11: =SUM(PRODUCTS!$D$5:$D$2000) | G11: =COUNTIFS(PRODUCTS!$A$5:$A$2000,"<>",PRODUCTS!$D$5:$D$2000,"<="&$B$5)
A13: Product summary (date range applies to Sold / Purchased; In Stock is current)
A14: Product Code | B14: Product Name | C14: Qty Sold | D14: Sales Amount | E14: Qty Purchased | F14: In Stock | G14: Stock Status
A15: =IFERROR(INDEX(PRODUCTS!$A$5:$A$2000,1)&"","") | B15: =IF(A15="","",INDEX(PRODUCTS!$B$5:$B$2000,1)) | C15: =IF(A15="","",SUMIFS(SALES!$H$5:$H$2000,SALES!$D$5:$D$2000,A15,SALES!$B$5:$B$2000,">="&$B$3,SALES!$B$5:$B$2000,"<="&$B$4)) | D15: =IF(A15="","",SUMIFS(SALES!$I$5:$I$2000,SALES!$D$5:$D$2000,A15,SALES!$B$5:$B$2000,">="&$B$3,SALES!$B$5:$B$2000,"<="&$B$4)) | E15: =IF(A15="","",SUMIFS(PURCHASE!$E$5:$E$2000,PURCHASE!$C$5:$C$2000,A15,PURCHASE!$B$5:$B$2000,">="&$B$3,PURCHASE!$B$5:$B$2000,"<="&$B$4)) | F15: =IF(A15="","",INDEX(PRODUCTS!$D$5:$D$2000,1)) | G15: =IF(A15="","",IF(F15<=0,"OUT OF STOCK",IF(F15<=$B$5,"LOW","OK")))
A16: =IFERROR(INDEX(PRODUCTS!$A$5:$A$2000,2)&"","") | B16: =IF(A16="","",INDEX(PRODUCTS!$B$5:$B$2000,2)) | C16: =IF(A16="","",SUMIFS(SALES!$H$5:$H$2000,SALES!$D$5:$D$2000,A16,SALES!$B$5:$B$2000,">="&$B$3,SALES!$B$5:$B$2000,"<="&$B$4)) | D16: =IF(A16="","",SUMIFS(SALES!$I$5:$I$2000,SALES!$D$5:$D$2000,A16,SALES!$B$5:$B$2000,">="&$B$3,SALES!$B$5:$B$2000,"<="&$B$4)) | E16: =IF(A16="","",SUMIFS(PURCHASE!$E$5:$E$2000,PURCHASE!$C$5:$C$2000,A16,PURCHASE!$B$5:$B$2000,">="&$B$3,PURCHASE!$B$5:$B$2000,"<="&$B$4)) | F16: =IF(A16="","",INDEX(PRODUCTS!$D$5:$D$2000,2)) | G16: =IF(A16="","",IF(F16<=0,"OUT OF STOCK",IF(F16<=$B$5,"LOW","OK")))
A17: =IFERROR(INDEX(PRODUCTS!$A$5:$A$2000,3)&"","") | B17: =IF(A17="","",INDEX(PRODUCTS!$B$5:$B$2000,3)) | C17: =IF(A17="","",SUMIFS(SALES!$H$5:$H$2000,SALES!$D$5:$D$2000,A17,SALES!$B$5:$B$2000,">="&$B$3,SALES!$B$5:$B$2000,"<="&$B$4)) | D17: =IF(A17="","",SUMIFS(SALES!$I$5:$I$2000,SALES!$D$5:$D$2000,A17,SALES!$B$5:$B$2000,">="&$B$3,SALES!$B$5:$B$2000,"<="&$B$4)) | E17: =IF(A17="","",SUMIFS(PURCHASE!$E$5:$E$2000,PURCHASE!$C$5:$C$2000,A17,PURCHASE!$B$5:$B$2000,">="&$B$3,PURCHASE!$B$5:$B$2000,"<="&$B$4)) | F17: =IF(A17="","",INDEX(PRODUCTS!$D$5:$D$2000,3)) | G17: =IF(A17="","",IF(F17<=0,"OUT OF STOCK",IF(F17<=$B$5,"LOW","OK")))
A18: =IFERROR(INDEX(PRODUCTS!$A$5:$A$2000,4)&"","") | B18: =IF(A18="","",INDEX(PRODUCTS!$B$5:$B$2000,4)) | C18: =IF(A18="","",SUMIFS(SALES!$H$5:$H$2000,SALES!$D$5:$D$2000,A18,SALES!$B$5:$B$2000,">="&$B$3,SALES!$B$5:$B$2000,"<="&$B$4)) | D18: =IF(A18="","",SUMIFS(SALES!$I$5:$I$2000,SALES!$D$5:$D$2000,A18,SALES!$B$5:$B$2000,">="&$B$3,SALES!$B$5:$B$2000,"<="&$B$4)) | E18: =IF(A18="","",SUMIFS(PURCHASE!$E$5:$E$2000,PURCHASE!$C$5:$C$2000,A18,PURCHASE!$B$5:$B$2000,">="&$B$3,PURCHASE!$B$5:$B$2000,"<="&$B$4)) | F18: =IF(A18="","",INDEX(PRODUCTS!$D$5:$D$2000,4)) | G18: =IF(A18="","",IF(F18<=0,"OUT OF STOCK",IF(F18<=$B$5,"LOW","OK")))
A19: =IFERROR(INDEX(PRODUCTS!$A$5:$A$2000,5)&"","") | B19: =IF(A19="","",INDEX(PRODUCTS!$B$5:$B$2000,5)) | C19: =IF(A19="","",SUMIFS(SALES!$H$5:$H$2000,SALES!$D$5:$D$2000,A19,SALES!$B$5:$B$2000,">="&$B$3,SALES!$B$5:$B$2000,"<="&$B$4)) | D19: =IF(A19="","",SUMIFS(SALES!$I$5:$I$2000,SALES!$D$5:$D$2000,A19,SALES!$B$5:$B$2000,">="&$B$3,SALES!$B$5:$B$2000,"<="&$B$4)) | E19: =IF(A19="","",SUMIFS(PURCHASE!$E$5:$E$2000,PURCHASE!$C$5:$C$2000,A19,PURCHASE!$B$5:$B$2000,">="&$B$3,PURCHASE!$B$5:$B$2000,"<="&$B$4)) | F19: =IF(A19="","",INDEX(PRODUCTS!$D$5:$D$2000,5)) | G19: =IF(A19="","",IF(F19<=0,"OUT OF STOCK",IF(F19<=$B$5,"LOW","OK")))
A20: =IFERROR(INDEX(PRODUCTS!$A$5:$A$2000,6)&"","") | B20: =IF(A20="","",INDEX(PRODUCTS!$B$5:$B$2000,6)) | C20: =IF(A20="","",SUMIFS(SALES!$H$5:$H$2000,SALES!$D$5:$D$2000,A20,SALES!$B$5:$B$2000,">="&$B$3,SALES!$B$5:$B$2000,"<="&$B$4)) | D20: =IF(A20="","",SUMIFS(SALES!$I$5:$I$2000,SALES!$D$5:$D$2000,A20,SALES!$B$5:$B$2000,">="&$B$3,SALES!$B$5:$B$2000,"<="&$B$4)) | E20: =IF(A20="","",SUMIFS(PURCHASE!$E$5:$E$2000,PURCHASE!$C$5:$C$2000,A20,PURCHASE!$B$5:$B$2000,">="&$B$3,PURCHASE!$B$5:$B$2000,"<="&$B$4)) | F20: =IF(A20="","",INDEX(PRODUCTS!$D$5:$D$2000,6)) | G20: =IF(A20="","",IF(F20<=0,"OUT OF STOCK",IF(F20<=$B$5,"LOW","OK")))
A21: =IFERROR(INDEX(PRODUCTS!$A$5:$A$2000,7)&"","") | B21: =IF(A21="","",INDEX(PRODUCTS!$B$5:$B$2000,7)) | C21: =IF(A21="","",SUMIFS(SALES!$H$5:$H$2000,SALES!$D$5:$D$2000,A21,SALES!$B$5:$B$2000,">="&$B$3,SALES!$B$5:$B$2000,"<="&$B$4)) | D21: =IF(A21="","",SUMIFS(SALES!$I$5:$I$2000,SALES!$D$5:$D$2000,A21,SALES!$B$5:$B$2000,">="&$B$3,SALES!$B$5:$B$2000,"<="&$B$4)) | E21: =IF(A21="","",SUMIFS(PURCHASE!$E$5:$E$2000,PURCHASE!$C$5:$C$2000,A21,PURCHASE!$B$5:$B$2000,">="&$B$3,PURCHASE!$B$5:$B$2000,"<="&$B$4)) | F21: =IF(A21="","",INDEX(PRODUCTS!$D$5:$D$2000,7)) | G21: =IF(A21="","",IF(F21<=0,"OUT OF STOCK",IF(F21<=$B$5,"LOW","OK")))
A22: =IFERROR(INDEX(PRODUCTS!$A$5:$A$2000,8)&"","") | B22: =IF(A22="","",INDEX(PRODUCTS!$B$5:$B$2000,8)) | C22: =IF(A22="","",SUMIFS(SALES!$H$5:$H$2000,SALES!$D$5:$D$2000,A22,SALES!$B$5:$B$2000,">="&$B$3,SALES!$B$5:$B$2000,"<="&$B$4)) | D22: =IF(A22="","",SUMIFS(SALES!$I$5:$I$2000,SALES!$D$5:$D$2000,A22,SALES!$B$5:$B$2000,">="&$B$3,SALES!$B$5:$B$2000,"<="&$B$4)) | E22: =IF(A22="","",SUMIFS(PURCHASE!$E$5:$E$2000,PURCHASE!$C$5:$C$2000,A22,PURCHASE!$B$5:$B$2000,">="&$B$3,PURCHASE!$B$5:$B$2000,"<="&$B$4)) | F22: =IF(A22="","",INDEX(PRODUCTS!$D$5:$D$2000,8)) | G22: =IF(A22="","",IF(F22<=0,"OUT OF STOCK",IF(F22<=$B$5,"LOW","OK")))
A23: =IFERROR(INDEX(PRODUCTS!$A$5:$A$2000,9)&"","") | B23: =IF(A23="","",INDEX(PRODUCTS!$B$5:$B$2000,9)) | C23: =IF(A23="","",SUMIFS(SALES!$H$5:$H$2000,SALES!$D$5:$D$2000,A23,SALES!$B$5:$B$2000,">="&$B$3,SALES!$B$5:$B$2000,"<="&$B$4)) | D23: =IF(A23="","",SUMIFS(SALES!$I$5:$I$2000,SALES!$D$5:$D$2000,A23,SALES!$B$5:$B$2000,">="&$B$3,SALES!$B$5:$B$2000,"<="&$B$4)) | E23: =IF(A23="","",SUMIFS(PURCHASE!$E$5:$E$2000,PURCHASE!$C$5:$C$2000,A23,PURCHASE!$B$5:$B$2000,">="&$B$3,PURCHASE!$B$5:$B$2000,"<="&$B$4)) | F23: =IF(A23="","",INDEX(PRODUCTS!$D$5:$D$2000,9)) | G23: =IF(A23="","",IF(F23<=0,"OUT OF STOCK",IF(F23<=$B$5,"LOW","OK")))
A24: =IFERROR(INDEX(PRODUCTS!$A$5:$A$2000,10)&"","") | B24: =IF(A24="","",INDEX(PRODUCTS!$B$5:$B$2000,10)) | C24: =IF(A24="","",SUMIFS(SALES!$H$5:$H$2000,SALES!$D$5:$D$2000,A24,SALES!$B$5:$B$2000,">="&$B$3,SALES!$B$5:$B$2000,"<="&$B$4)) | D24: =IF(A24="","",SUMIFS(SALES!$I$5:$I$2000,SALES!$D$5:$D$2000,A24,SALES!$B$5:$B$2000,">="&$B$3,SALES!$B$5:$B$2000,"<="&$B$4)) | E24: =IF(A24="","",SUMIFS(PURCHASE!$E$5:$E$2000,PURCHASE!$C$5:$C$2000,A24,PURCHASE!$B$5:$B$2000,">="&$B$3,PURCHASE!$B$5:$B$2000,"<="&$B$4)) | F24: =IF(A24="","",INDEX(PRODUCTS!$D$5:$D$2000,10)) | G24: =IF(A24="","",IF(F24<=0,"OUT OF STOCK",IF(F24<=$B$5,"LOW","OK")))
A25: =IFERROR(INDEX(PRODUCTS!$A$5:$A$2000,11)&"","") | B25: =IF(A25="","",INDEX(PRODUCTS!$B$5:$B$2000,11)) | C25: =IF(A25="","",SUMIFS(SALES!$H$5:$H$2000,SALES!$D$5:$D$2000,A25,SALES!$B$5:$B$2000,">="&$B$3,SALES!$B$5:$B$2000,"<="&$B$4)) | D25: =IF(A25="","",SUMIFS(SALES!$I$5:$I$2000,SALES!$D$5:$D$2000,A25,SALES!$B$5:$B$2000,">="&$B$3,SALES!$B$5:$B$2000,"<="&$B$4)) | E25: =IF(A25="","",SUMIFS(PURCHASE!$E$5:$E$2000,PURCHASE!$C$5:$C$2000,A25,PURCHASE!$B$5:$B$2000,">="&$B$3,PURCHASE!$B$5:$B$2000,"<="&$B$4)) | F25: =IF(A25="","",INDEX(PRODUCTS!$D$5:$D$2000,11)) | G25: =IF(A25="","",IF(F25<=0,"OUT OF STOCK",IF(F25<=$B$5,"LOW","OK")))
A26: =IFERROR(INDEX(PRODUCTS!$A$5:$A$2000,12)&"","") | B26: =IF(A26="","",INDEX(PRODUCTS!$B$5:$B$2000,12)) | C26: =IF(A26="","",SUMIFS(SALES!$H$5:$H$2000,SALES!$D$5:$D$2000,A26,SALES!$B$5:$B$2000,">="&$B$3,SALES!$B$5:$B$2000,"<="&$B$4)) | D26: =IF(A26="","",SUMIFS(SALES!$I$5:$I$2000,SALES!$D$5:$D$2000,A26,SALES!$B$5:$B$2000,">="&$B$3,SALES!$B$5:$B$2000,"<="&$B$4)) | E26: =IF(A26="","",SUMIFS(PURCHASE!$E$5:$E$2000,PURCHASE!$C$5:$C$2000,A26,PURCHASE!$B$5:$B$2000,">="&$B$3,PURCHASE!$B$5:$B$2000,"<="&$B$4)) | F26: =IF(A26="","",INDEX(PRODUCTS!$D$5:$D$2000,12)) | G26: =IF(A26="","",IF(F26<=0,"OUT OF STOCK",IF(F26<=$B$5,"LOW","OK")))
A27: Shows the first 12 products in PRODUCTS.
A30: Sales between the selected dates
A31: Order No. | B31: Date | C31: Customer | D31: Product Code | E31: Product Name | F31: Qty | G31: Net Amount | L31: helper
A32: =IF($L32="","",INDEX(SALES!$A$5:$A$2000,$L32)) | B32: =IF($L32="","",INDEX(SALES!$B$5:$B$2000,$L32)) | C32: =IF($L32="","",INDEX(SALES!$C$5:$C$2000,$L32)) | D32: =IF($L32="","",INDEX(SALES!$D$5:$D$2000,$L32)) | E32: =IF($L32="","",INDEX(SALES!$E$5:$E$2000,$L32)) | F32: =IF($L32="","",INDEX(SALES!$H$5:$H$2000,$L32)) | G32: =IF($L32="","",INDEX(SALES!$I$5:$I$2000,$L32)) | L32: =IFERROR(IF(SUMPRODUCT(SMALL(((SALES!$B$5:$B$2000>=$B$3)*(SALES!$B$5:$B$2000<=$B$4)*(SALES!$B$5:$B$2000<>""))*(ROW(SALES!$B$5:$B$2000)-4)+(1-(SALES!$B$5:$B$2000>=$B$3)*(SALES!$B$5:$B$2000<=$B$4)*(SALES!$B$5:$B$2000<>""))*1000000,1))>=1000000,"",SUMPRODUCT(SMALL(((SALES!$B$5:$B$2000>=$B$3)*(SALES!$B$5:$B$2000<=$B$4)*(SALES!$B$5:$B$2000<>""))*(ROW(SALES!$B$5:$B$2000)-4)+(1-(SALES!$B$5:$B$2000>=$B$3)*(SALES!$B$5:$B$2000<=$B$4)*(SALES!$B$5:$B$2000<>""))*1000000,1))),"")
A33: =IF($L33="","",INDEX(SALES!$A$5:$A$2000,$L33)) | B33: =IF($L33="","",INDEX(SALES!$B$5:$B$2000,$L33)) | C33: =IF($L33="","",INDEX(SALES!$C$5:$C$2000,$L33)) | D33: =IF($L33="","",INDEX(SALES!$D$5:$D$2000,$L33)) | E33: =IF($L33="","",INDEX(SALES!$E$5:$E$2000,$L33)) | F33: =IF($L33="","",INDEX(SALES!$H$5:$H$2000,$L33)) | G33: =IF($L33="","",INDEX(SALES!$I$5:$I$2000,$L33)) | L33: =IFERROR(IF(SUMPRODUCT(SMALL(((SALES!$B$5:$B$2000>=$B$3)*(SALES!$B$5:$B$2000<=$B$4)*(SALES!$B$5:$B$2000<>""))*(ROW(SALES!$B$5:$B$2000)-4)+(1-(SALES!$B$5:$B$2000>=$B$3)*(SALES!$B$5:$B$2000<=$B$4)*(SALES!$B$5:$B$2000<>""))*1000000,2))>=1000000,"",SUMPRODUCT(SMALL(((SALES!$B$5:$B$2000>=$B$3)*(SALES!$B$5:$B$2000<=$B$4)*(SALES!$B$5:$B$2000<>""))*(ROW(SALES!$B$5:$B$2000)-4)+(1-(SALES!$B$5:$B$2000>=$B$3)*(SALES!$B$5:$B$2000<=$B$4)*(SALES!$B$5:$B$2000<>""))*1000000,2))),"")
A34: =IF($L34="","",INDEX(SALES!$A$5:$A$2000,$L34)) | B34: =IF($L34="","",INDEX(SALES!$B$5:$B$2000,$L34)) | C34: =IF($L34="","",INDEX(SALES!$C$5:$C$2000,$L34)) | D34: =IF($L34="","",INDEX(SALES!$D$5:$D$2000,$L34)) | E34: =IF($L34="","",INDEX(SALES!$E$5:$E$2000,$L34)) | F34: =IF($L34="","",INDEX(SALES!$H$5:$H$2000,$L34)) | G34: =IF($L34="","",INDEX(SALES!$I$5:$I$2000,$L34)) | L34: =IFERROR(IF(SUMPRODUCT(SMALL(((SALES!$B$5:$B$2000>=$B$3)*(SALES!$B$5:$B$2000<=$B$4)*(SALES!$B$5:$B$2000<>""))*(ROW(SALES!$B$5:$B$2000)-4)+(1-(SALES!$B$5:$B$2000>=$B$3)*(SALES!$B$5:$B$2000<=$B$4)*(SALES!$B$5:$B$2000<>""))*1000000,3))>=1000000,"",SUMPRODUCT(SMALL(((SALES!$B$5:$B$2000>=$B$3)*(SALES!$B$5:$B$2000<=$B$4)*(SALES!$B$5:$B$2000<>""))*(ROW(SALES!$B$5:$B$2000)-4)+(1-(SALES!$B$5:$B$2000>=$B$3)*(SALES!$B$5:$B$2000<=$B$4)*(SALES!$B$5:$B$2000<>""))*1000000,3))),"")
A35: =IF($L35="","",INDEX(SALES!$A$5:$A$2000,$L35)) | B35: =IF($L35="","",INDEX(SALES!$B$5:$B$2000,$L35)) | C35: =IF($L35="","",INDEX(SALES!$C$5:$C$2000,$L35)) | D35: =IF($L35="","",INDEX(SALES!$D$5:$D$2000,$L35)) | E35: =IF($L35="","",INDEX(SALES!$E$5:$E$2000,$L35)) | F35: =IF($L35="","",INDEX(SALES!$H$5:$H$2000,$L35)) | G35: =IF($L35="","",INDEX(SALES!$I$5:$I$2000,$L35)) | L35: =IFERROR(IF(SUMPRODUCT(SMALL(((SALES!$B$5:$B$2000>=$B$3)*(SALES!$B$5:$B$2000<=$B$4)*(SALES!$B$5:$B$2000<>""))*(ROW(SALES!$B$5:$B$2000)-4)+(1-(SALES!$B$5:$B$2000>=$B$3)*(SALES!$B$5:$B$2000<=$B$4)*(SALES!$B$5:$B$2000<>""))*1000000,4))>=1000000,"",SUMPRODUCT(SMALL(((SALES!$B$5:$B$2000>=$B$3)*(SALES!$B$5:$B$2000<=$B$4)*(SALES!$B$5:$B$2000<>""))*(ROW(SALES!$B$5:$B$2000)-4)+(1-(SALES!$B$5:$B$2000>=$B$3)*(SALES!$B$5:$B$2000<=$B$4)*(SALES!$B$5:$B$2000<>""))*1000000,4))),"")
A36: =IF($L36="","",INDEX(SALES!$A$5:$A$2000,$L36)) | B36: =IF($L36="","",INDEX(SALES!$B$5:$B$2000,$L36)) | C36: =IF($L36="","",INDEX(SALES!$C$5:$C$2000,$L36)) | D36: =IF($L36="","",INDEX(SALES!$D$5:$D$2000,$L36)) | E36: =IF($L36="","",INDEX(SALES!$E$5:$E$2000,$L36)) | F36: =IF($L36="","",INDEX(SALES!$H$5:$H$2000,$L36)) | G36: =IF($L36="","",INDEX(SALES!$I$5:$I$2000,$L36)) | L36: =IFERROR(IF(SUMPRODUCT(SMALL(((SALES!$B$5:$B$2000>=$B$3)*(SALES!$B$5:$B$2000<=$B$4)*(SALES!$B$5:$B$2000<>""))*(ROW(SALES!$B$5:$B$2000)-4)+(1-(SALES!$B$5:$B$2000>=$B$3)*(SALES!$B$5:$B$2000<=$B$4)*(SALES!$B$5:$B$2000<>""))*1000000,5))>=1000000,"",SUMPRODUCT(SMALL(((SALES!$B$5:$B$2000>=$B$3)*(SALES!$B$5:$B$2000<=$B$4)*(SALES!$B$5:$B$2000<>""))*(ROW(SALES!$B$5:$B$2000)-4)+(1-(SALES!$B$5:$B$2000>=$B$3)*(SALES!$B$5:$B$2000<=$B$4)*(SALES!$B$5:$B$2000<>""))*1000000,5))),"")
A37: =IF($L37="","",INDEX(SALES!$A$5:$A$2000,$L37)) | B37: =IF($L37="","",INDEX(SALES!$B$5:$B$2000,$L37)) | C37: =IF($L37="","",INDEX(SALES!$C$5:$C$2000,$L37)) | D37: =IF($L37="","",INDEX(SALES!$D$5:$D$2000,$L37)) | E37: =IF($L37="","",INDEX(SALES!$E$5:$E$2000,$L37)) | F37: =IF($L37="","",INDEX(SALES!$H$5:$H$2000,$L37)) | G37: =IF($L37="","",INDEX(SALES!$I$5:$I$2000,$L37)) | L37: =IFERROR(IF(SUMPRODUCT(SMALL(((SALES!$B$5:$B$2000>=$B$3)*(SALES!$B$5:$B$2000<=$B$4)*(SALES!$B$5:$B$2000<>""))*(ROW(SALES!$B$5:$B$2000)-4)+(1-(SALES!$B$5:$B$2000>=$B$3)*(SALES!$B$5:$B$2000<=$B$4)*(SALES!$B$5:$B$2000<>""))*1000000,6))>=1000000,"",SUMPRODUCT(SMALL(((SALES!$B$5:$B$2000>=$B$3)*(SALES!$B$5:$B$2000<=$B$4)*(SALES!$B$5:$B$2000<>""))*(ROW(SALES!$B$5:$B$2000)-4)+(1-(SALES!$B$5:$B$2000>=$B$3)*(SALES!$B$5:$B$2000<=$B$4)*(SALES!$B$5:$B$2000<>""))*1000000,6))),"")
A38: =IF($L38="","",INDEX(SALES!$A$5:$A$2000,$L38)) | B38: =IF($L38="","",INDEX(SALES!$B$5:$B$2000,$L38)) | C38: =IF($L38="","",INDEX(SALES!$C$5:$C$2000,$L38)) | D38: =IF($L38="","",INDEX(SALES!$D$5:$D$2000,$L38)) | E38: =IF($L38="","",INDEX(SALES!$E$5:$E$2000,$L38)) | F38: =IF($L38="","",INDEX(SALES!$H$5:$H$2000,$L38)) | G38: =IF($L38="","",INDEX(SALES!$I$5:$I$2000,$L38)) | L38: =IFERROR(IF(SUMPRODUCT(SMALL(((SALES!$B$5:$B$2000>=$B$3)*(SALES!$B$5:$B$2000<=$B$4)*(SALES!$B$5:$B$2000<>""))*(ROW(SALES!$B$5:$B$2000)-4)+(1-(SALES!$B$5:$B$2000>=$B$3)*(SALES!$B$5:$B$2000<=$B$4)*(SALES!$B$5:$B$2000<>""))*1000000,7))>=1000000,"",SUMPRODUCT(SMALL(((SALES!$B$5:$B$2000>=$B$3)*(SALES!$B$5:$B$2000<=$B$4)*(SALES!$B$5:$B$2000<>""))*(ROW(SALES!$B$5:$B$2000)-4)+(1-(SALES!$B$5:$B$2000>=$B$3)*(SALES!$B$5:$B$2000<=$B$4)*(SALES!$B$5:$B$2000<>""))*1000000,7))),"")
A39: =IF($L39="","",INDEX(SALES!$A$5:$A$2000,$L39)) | B39: =IF($L39="","",INDEX(SALES!$B$5:$B$2000,$L39)) | C39: =IF($L39="","",INDEX(SALES!$C$5:$C$2000,$L39)) | D39: =IF($L39="","",INDEX(SALES!$D$5:$D$2000,$L39)) | E39: =IF($L39="","",INDEX(SALES!$E$5:$E$2000,$L39)) | F39: =IF($L39="","",INDEX(SALES!$H$5:$H$2000,$L39)) | G39: =IF($L39="","",INDEX(SALES!$I$5:$I$2000,$L39)) | L39: =IFERROR(IF(SUMPRODUCT(SMALL(((SALES!$B$5:$B$2000>=$B$3)*(SALES!$B$5:$B$2000<=$B$4)*(SALES!$B$5:$B$2000<>""))*(ROW(SALES!$B$5:$B$2000)-4)+(1-(SALES!$B$5:$B$2000>=$B$3)*(SALES!$B$5:$B$2000<=$B$4)*(SALES!$B$5:$B$2000<>""))*1000000,8))>=1000000,"",SUMPRODUCT(SMALL(((SALES!$B$5:$B$2000>=$B$3)*(SALES!$B$5:$B$2000<=$B$4)*(SALES!$B$5:$B$2000<>""))*(ROW(SALES!$B$5:$B$2000)-4)+(1-(SALES!$B$5:$B$2000>=$B$3)*(SALES!$B$5:$B$2000<=$B$4)*(SALES!$B$5:$B$2000<>""))*1000000,8))),"")
A40: =IF($L40="","",INDEX(SALES!$A$5:$A$2000,$L40)) | B40: =IF($L40="","",INDEX(SALES!$B$5:$B$2000,$L40)) | C40: =IF($L40="","",INDEX(SALES!$C$5:$C$2000,$L40)) | D40: =IF($L40="","",INDEX(SALES!$D$5:$D$2000,$L40)) | E40: =IF($L40="","",INDEX(SALES!$E$5:$E$2000,$L40)) | F40: =IF($L40="","",INDEX(SALES!$H$5:$H$2000,$L40)) | G40: =IF($L40="","",INDEX(SALES!$I$5:$I$2000,$L40)) | L40: =IFERROR(IF(SUMPRODUCT(SMALL(((SALES!$B$5:$B$2000>=$B$3)*(SALES!$B$5:$B$2000<=$B$4)*(SALES!$B$5:$B$2000<>""))*(ROW(SALES!$B$5:$B$2000)-4)+(1-(SALES!$B$5:$B$2000>=$B$3)*(SALES!$B$5:$B$2000<=$B$4)*(SALES!$B$5:$B$2000<>""))*1000000,9))>=1000000,"",SUMPRODUCT(SMALL(((SALES!$B$5:$B$2000>=$B$3)*(SALES!$B$5:$B$2000<=$B$4)*(SALES!$B$5:$B$2000<>""))*(ROW(SALES!$B$5:$B$2000)-4)+(1-(SALES!$B$5:$B$2000>=$B$3)*(SALES!$B$5:$B$2000<=$B$4)*(SALES!$B$5:$B$2000<>""))*1000000,9))),"")
A41: =IF($L41="","",INDEX(SALES!$A$5:$A$2000,$L41)) | B41: =IF($L41="","",INDEX(SALES!$B$5:$B$2000,$L41)) | C41: =IF($L41="","",INDEX(SALES!$C$5:$C$2000,$L41)) | D41: =IF($L41="","",INDEX(SALES!$D$5:$D$2000,$L41)) | E41: =IF($L41="","",INDEX(SALES!$E$5:$E$2000,$L41)) | F41: =IF($L41="","",INDEX(SALES!$H$5:$H$2000,$L41)) | G41: =IF($L41="","",INDEX(SALES!$I$5:$I$2000,$L41)) | L41: =IFERROR(IF(SUMPRODUCT(SMALL(((SALES!$B$5:$B$2000>=$B$3)*(SALES!$B$5:$B$2000<=$B$4)*(SALES!$B$5:$B$2000<>""))*(ROW(SALES!$B$5:$B$2000)-4)+(1-(SALES!$B$5:$B$2000>=$B$3)*(SALES!$B$5:$B$2000<=$B$4)*(SALES!$B$5:$B$2000<>""))*1000000,10))>=1000000,"",SUMPRODUCT(SMALL(((SALES!$B$5:$B$2000>=$B$3)*(SALES!$B$5:$B$2000<=$B$4)*(SALES!$B$5:$B$2000<>""))*(ROW(SALES!$B$5:$B$2000)-4)+(1-(SALES!$B$5:$B$2000>=$B$3)*(SALES!$B$5:$B$2000<=$B$4)*(SALES!$B$5:$B$2000<>""))*1000000,10))),"")
A42: =IF($L42="","",INDEX(SALES!$A$5:$A$2000,$L42)) | B42: =IF($L42="","",INDEX(SALES!$B$5:$B$2000,$L42)) | C42: =IF($L42="","",INDEX(SALES!$C$5:$C$2000,$L42)) | D42: =IF($L42="","",INDEX(SALES!$D$5:$D$2000,$L42)) | E42: =IF($L42="","",INDEX(SALES!$E$5:$E$2000,$L42)) | F42: =IF($L42="","",INDEX(SALES!$H$5:$H$2000,$L42)) | G42: =IF($L42="","",INDEX(SALES!$I$5:$I$2000,$L42)) | L42: =IFERROR(IF(SUMPRODUCT(SMALL(((SALES!$B$5:$B$2000>=$B$3)*(SALES!$B$5:$B$2000<=$B$4)*(SALES!$B$5:$B$2000<>""))*(ROW(SALES!$B$5:$B$2000)-4)+(1-(SALES!$B$5:$B$2000>=$B$3)*(SALES!$B$5:$B$2000<=$B$4)*(SALES!$B$5:$B$2000<>""))*1000000,11))>=1000000,"",SUMPRODUCT(SMALL(((SALES!$B$5:$B$2000>=$B$3)*(SALES!$B$5:$B$2000<=$B$4)*(SALES!$B$5:$B$2000<>""))*(ROW(SALES!$B$5:$B$2000)-4)+(1-(SALES!$B$5:$B$2000>=$B$3)*(SALES!$B$5:$B$2000<=$B$4)*(SALES!$B$5:$B$2000<>""))*1000000,11))),"")
A43: =IF($L43="","",INDEX(SALES!$A$5:$A$2000,$L43)) | B43: =IF($L43="","",INDEX(SALES!$B$5:$B$2000,$L43)) | C43: =IF($L43="","",INDEX(SALES!$C$5:$C$2000,$L43)) | D43: =IF($L43="","",INDEX(SALES!$D$5:$D$2000,$L43)) | E43: =IF($L43="","",INDEX(SALES!$E$5:$E$2000,$L43)) | F43: =IF($L43="","",INDEX(SALES!$H$5:$H$2000,$L43)) | G43: =IF($L43="","",INDEX(SALES!$I$5:$I$2000,$L43)) | L43: =IFERROR(IF(SUMPRODUCT(SMALL(((SALES!$B$5:$B$2000>=$B$3)*(SALES!$B$5:$B$2000<=$B$4)*(SALES!$B$5:$B$2000<>""))*(ROW(SALES!$B$5:$B$2000)-4)+(1-(SALES!$B$5:$B$2000>=$B$3)*(SALES!$B$5:$B$2000<=$B$4)*(SALES!$B$5:$B$2000<>""))*1000000,12))>=1000000,"",SUMPRODUCT(SMALL(((SALES!$B$5:$B$2000>=$B$3)*(SALES!$B$5:$B$2000<=$B$4)*(SALES!$B$5:$B$2000<>""))*(ROW(SALES!$B$5:$B$2000)-4)+(1-(SALES!$B$5:$B$2000>=$B$3)*(SALES!$B$5:$B$2000<=$B$4)*(SALES!$B$5:$B$2000<>""))*1000000,12))),"")
A44: =IF($L44="","",INDEX(SALES!$A$5:$A$2000,$L44)) | B44: =IF($L44="","",INDEX(SALES!$B$5:$B$2000,$L44)) | C44: =IF($L44="","",INDEX(SALES!$C$5:$C$2000,$L44)) | D44: =IF($L44="","",INDEX(SALES!$D$5:$D$2000,$L44)) | E44: =IF($L44="","",INDEX(SALES!$E$5:$E$2000,$L44)) | F44: =IF($L44="","",INDEX(SALES!$H$5:$H$2000,$L44)) | G44: =IF($L44="","",INDEX(SALES!$I$5:$I$2000,$L44)) | L44: =IFERROR(IF(SUMPRODUCT(SMALL(((SALES!$B$5:$B$2000>=$B$3)*(SALES!$B$5:$B$2000<=$B$4)*(SALES!$B$5:$B$2000<>""))*(ROW(SALES!$B$5:$B$2000)-4)+(1-(SALES!$B$5:$B$2000>=$B$3)*(SALES!$B$5:$B$2000<=$B$4)*(SALES!$B$5:$B$2000<>""))*1000000,13))>=1000000,"",SUMPRODUCT(SMALL(((SALES!$B$5:$B$2000>=$B$3)*(SALES!$B$5:$B$2000<=$B$4)*(SALES!$B$5:$B$2000<>""))*(ROW(SALES!$B$5:$B$2000)-4)+(1-(SALES!$B$5:$B$2000>=$B$3)*(SALES!$B$5:$B$2000<=$B$4)*(SALES!$B$5:$B$2000<>""))*1000000,13))),"")
A45: =IF($L45="","",INDEX(SALES!$A$5:$A$2000,$L45)) | B45: =IF($L45="","",INDEX(SALES!$B$5:$B$2000,$L45)) | C45: =IF($L45="","",INDEX(SALES!$C$5:$C$2000,$L45)) | D45: =IF($L45="","",INDEX(SALES!$D$5:$D$2000,$L45)) | E45: =IF($L45="","",INDEX(SALES!$E$5:$E$2000,$L45)) | F45: =IF($L45="","",INDEX(SALES!$H$5:$H$2000,$L45)) | G45: =IF($L45="","",INDEX(SALES!$I$5:$I$2000,$L45)) | L45: =IFERROR(IF(SUMPRODUCT(SMALL(((SALES!$B$5:$B$2000>=$B$3)*(SALES!$B$5:$B$2000<=$B$4)*(SALES!$B$5:$B$2000<>""))*(ROW(SALES!$B$5:$B$2000)-4)+(1-(SALES!$B$5:$B$2000>=$B$3)*(SALES!$B$5:$B$2000<=$B$4)*(SALES!$B$5:$B$2000<>""))*1000000,14))>=1000000,"",SUMPRODUCT(SMALL(((SALES!$B$5:$B$2000>=$B$3)*(SALES!$B$5:$B$2000<=$B$4)*(SALES!$B$5:$B$2000<>""))*(ROW(SALES!$B$5:$B$2000)-4)+(1-(SALES!$B$5:$B$2000>=$B$3)*(SALES!$B$5:$B$2000<=$B$4)*(SALES!$B$5:$B$2000<>""))*1000000,14))),"")
...

Sheet PRODUCTS
A1: Happy Hatch – PRODUCTS
A2: Blue = enter / edit. Black = automatic formula (do not overwrite). In Stock = total PURCHASE qty − total SALES qty. Revenue = profit per unit (Net Price − Onboard Price).
A3: Photo File = path of the product image in the Product_Photos folder (named <Product Code>.jpg). Product photos float over column L: after sorting/filtering, drag a photo back onto its row. Add a new photo via Insert > Pictures and size it to the row.
A4: Product Code | B4: Product Name | C4: Specification | D4: In Stock | E4: Base Price | F4: Transit Charges | G4: Onboard Price | H4: Profitability Percentage | I4: Net Price | J4: Market Price | K4: Revenue | L4: Product Photo | M4: Photo File | N4: Remarks
A5: HH000101 | B5: Whisk-4383 Egg Beater with Wooden Handle | C5: Item ref NN88. Silicone-wire whisk, wooden handle; green / white; 12 pcs per carton | D5: =SUMIFS(PURCHASE!$E$5:$E$2000,PURCHASE!$C$5:$C$2000,tblProducts[[#This Row],[Product Code]])-SUMIFS(SALES!$H$5:$H$2000,SALES!$D$5:$D$2000,tblProducts[[#This Row],[Product Code]]) | E5: 191 | F5: 12 | G5: =tblProducts[[#This Row],[Base Price]]+tblProducts[[#This Row],[Transit Charges]] | H5: 0.2 | I5: =tblProducts[[#This Row],[Onboard Price]]+tblProducts[[#This Row],[Profitability Percentage]]*tblProducts[[#This Row],[Onboard Price]] | J5: 399 | K5: =tblProducts[[#This Row],[Net Price]]-tblProducts[[#This Row],[Onboard Price]] | M5: Product_Photos/HH000101.jpg
A6: HH000102 | B6: Brush-1214 Silicone Brush | C6: Item ref NN95. Silicone dish brush; green / blue; 12 pcs per carton | D6: =SUMIFS(PURCHASE!$E$5:$E$2000,PURCHASE!$C$5:$C$2000,tblProducts[[#This Row],[Product Code]])-SUMIFS(SALES!$H$5:$H$2000,SALES!$D$5:$D$2000,tblProducts[[#This Row],[Product Code]]) | E6: 1108 | F6: 40 | G6: =tblProducts[[#This Row],[Base Price]]+tblProducts[[#This Row],[Transit Charges]] | H6: 0.2 | I6: =tblProducts[[#This Row],[Onboard Price]]+tblProducts[[#This Row],[Profitability Percentage]]*tblProducts[[#This Row],[Onboard Price]] | J6: 1999 | K6: =tblProducts[[#This Row],[Net Price]]-tblProducts[[#This Row],[Onboard Price]] | M6: Product_Photos/HH000102.jpg
A7: HH000103 | B7: Scissor-5199 European-Style Stationery Scissors | C7: Item ref NN99. Stationery scissors; green / blue; 12 pcs per carton | D7: =SUMIFS(PURCHASE!$E$5:$E$2000,PURCHASE!$C$5:$C$2000,tblProducts[[#This Row],[Product Code]])-SUMIFS(SALES!$H$5:$H$2000,SALES!$D$5:$D$2000,tblProducts[[#This Row],[Product Code]]) | E7: 183 | F7: 10 | G7: =tblProducts[[#This Row],[Base Price]]+tblProducts[[#This Row],[Transit Charges]] | H7: 0.2 | I7: =tblProducts[[#This Row],[Onboard Price]]+tblProducts[[#This Row],[Profitability Percentage]]*tblProducts[[#This Row],[Onboard Price]] | J7: 349 | K7: =tblProducts[[#This Row],[Net Price]]-tblProducts[[#This Row],[Onboard Price]] | M7: Product_Photos/HH000103.jpg
A8: HH000104 | B8: Peeler-9197 Y Shape Peeler | C8: Item ref NN82. Y-shape peeler, green handle; 12 pcs per carton | D8: =SUMIFS(PURCHASE!$E$5:$E$2000,PURCHASE!$C$5:$C$2000,tblProducts[[#This Row],[Product Code]])-SUMIFS(SALES!$H$5:$H$2000,SALES!$D$5:$D$2000,tblProducts[[#This Row],[Product Code]]) | E8: 1102 | F8: 40 | G8: =tblProducts[[#This Row],[Base Price]]+tblProducts[[#This Row],[Transit Charges]] | H8: 0.2 | I8: =tblProducts[[#This Row],[Onboard Price]]+tblProducts[[#This Row],[Profitability Percentage]]*tblProducts[[#This Row],[Onboard Price]] | J8: 1599 | K8: =tblProducts[[#This Row],[Net Price]]-tblProducts[[#This Row],[Onboard Price]] | M8: Product_Photos/HH000104.jpg
A9: HH000105 | B9: 2 Pieces Watercan Holder | C9: Item ref WCH-170 (no item no. on image). Felt carry holder for 2 bottles; carton = 170 pcs, min order 170 pcs | D9: =SUMIFS(PURCHASE!$E$5:$E$2000,PURCHASE!$C$5:$C$2000,tblProducts[[#This Row],[Product Code]])-SUMIFS(SALES!$H$5:$H$2000,SALES!$D$5:$D$2000,tblProducts[[#This Row],[Product Code]]) | E9: 38 | F9: 3 | G9: =tblProducts[[#This Row],[Base Price]]+tblProducts[[#This Row],[Transit Charges]] | H9: 0.2 | I9: =tblProducts[[#This Row],[Onboard Price]]+tblProducts[[#This Row],[Profitability Percentage]]*tblProducts[[#This Row],[Onboard Price]] | J9: 99 | K9: =tblProducts[[#This Row],[Net Price]]-tblProducts[[#This Row],[Onboard Price]] | M9: Product_Photos/HH000105.jpg
A10: HH000106 | B10: Sports Vacuum Bottle 2 Litres | C10: Item ref VB-2L (no item no. on image). Vacuum insulated, 2 L, olive green; 25 pcs per carton | D10: =SUMIFS(PURCHASE!$E$5:$E$2000,PURCHASE!$C$5:$C$2000,tblProducts[[#This Row],[Product Code]])-SUMIFS(SALES!$H$5:$H$2000,SALES!$D$5:$D$2000,tblProducts[[#This Row],[Product Code]]) | E10: 1870 | F10: 90 | G10: =tblProducts[[#This Row],[Base Price]]+tblProducts[[#This Row],[Transit Charges]] | H10: 0.2 | I10: =tblProducts[[#This Row],[Onboard Price]]+tblProducts[[#This Row],[Profitability Percentage]]*tblProducts[[#This Row],[Onboard Price]] | J10: 2999 | K10: =tblProducts[[#This Row],[Net Price]]-tblProducts[[#This Row],[Onboard Price]] | M10: Product_Photos/HH000106.jpg

Sheet SALES
A1: Happy Hatch – SALES
A2: Blue = enter / edit. One Order Number (HH_S000101, HH_S000102 ...) can have many rows - repeat the same Order Number, Date and Customer for each extra product. Customer Number & Product Code must exist in CUSTOMERS / PRODUCTS. Product Name and Product price (= Net Price from PRODUCTS) are looked up. Net Amount = MRP × Quantity. GST / CGST / SGST / IGST (%) are the tax rates for the order - repeat the same rates on every row of an order (the invoice uses the first row). Enter only the taxes that apply.
A4: Order Number | B4: Date of Sale | C4: Customer Number | D4: Product Code | E4: Product Name | F4: Product price | G4: MRP | H4: Quantity | I4: Net Amount | J4: GST (%) | K4: CGST (%) | L4: SGST (%) | M4: IGST (%) | N4: Invoice No. | O4: Remarks
A5: HH_S000101 | B5: 46283 | C5: CUS-001 | D5: HH000101 | E5: =IFERROR(INDEX(tblProducts[Product Name],MATCH(tblSales[[#This Row],[Product Code]],tblProducts[Product Code],0)),"") | F5: =IFERROR(INDEX(tblProducts[Net Price],MATCH(tblSales[[#This Row],[Product Code]],tblProducts[Product Code],0)),0) | G5: 399 | H5: 24 | I5: =tblSales[[#This Row],[MRP]]*tblSales[[#This Row],[Quantity]] | J5: 0 | K5: 0.09 | L5: 0.09 | M5: 0 | N5: ="INV-"&tblSales[[#This Row],[Order Number]]
A6: HH_S000102 | B6: 46287 | C6: CUS-002 | D6: HH000102 | E6: =IFERROR(INDEX(tblProducts[Product Name],MATCH(tblSales[[#This Row],[Product Code]],tblProducts[Product Code],0)),"") | F6: =IFERROR(INDEX(tblProducts[Net Price],MATCH(tblSales[[#This Row],[Product Code]],tblProducts[Product Code],0)),0) | G6: 1999 | H6: 12 | I6: =tblSales[[#This Row],[MRP]]*tblSales[[#This Row],[Quantity]] | J6: 0 | K6: 0 | L6: 0 | M6: 0.18 | N6: ="INV-"&tblSales[[#This Row],[Order Number]]
A7: HH_S000103 | B7: 46293 | C7: CUS-001 | D7: HH000103 | E7: =IFERROR(INDEX(tblProducts[Product Name],MATCH(tblSales[[#This Row],[Product Code]],tblProducts[Product Code],0)),"") | F7: =IFERROR(INDEX(tblProducts[Net Price],MATCH(tblSales[[#This Row],[Product Code]],tblProducts[Product Code],0)),0) | G7: 349 | H7: 36 | I7: =tblSales[[#This Row],[MRP]]*tblSales[[#This Row],[Quantity]] | J7: 0 | K7: 0.09 | L7: 0.09 | M7: 0 | N7: ="INV-"&tblSales[[#This Row],[Order Number]]
A8: HH_S000104 | B8: 46298 | C8: CUS-003 | D8: HH000105 | E8: =IFERROR(INDEX(tblProducts[Product Name],MATCH(tblSales[[#This Row],[Product Code]],tblProducts[Product Code],0)),"") | F8: =IFERROR(INDEX(tblProducts[Net Price],MATCH(tblSales[[#This Row],[Product Code]],tblProducts[Product Code],0)),0) | G8: 99 | H8: 170 | I8: =tblSales[[#This Row],[MRP]]*tblSales[[#This Row],[Quantity]] | J8: 0 | K8: 0 | L8: 0 | M8: 0.18 | N8: ="INV-"&tblSales[[#This Row],[Order Number]]
A9: HH_S000104 | B9: 46298 | C9: CUS-003 | D9: HH000106 | E9: =IFERROR(INDEX(tblProducts[Product Name],MATCH(tblSales[[#This Row],[Product Code]],tblProducts[Product Code],0)),"") | F9: =IFERROR(INDEX(tblProducts[Net Price],MATCH(tblSales[[#This Row],[Product Code]],tblProducts[Product Code],0)),0) | G9: 2999 | H9: 10 | I9: =tblSales[[#This Row],[MRP]]*tblSales[[#This Row],[Quantity]] | J9: 0 | K9: 0 | L9: 0 | M9: 0.18 | N9: ="INV-"&tblSales[[#This Row],[Order Number]]
A10: HH_S000105 | B10: 46300 | C10: CUS-001 | D10: HH000104 | E10: =IFERROR(INDEX(tblProducts[Product Name],MATCH(tblSales[[#This Row],[Product Code]],tblProducts[Product Code],0)),"") | F10: =IFERROR(INDEX(tblProducts[Net Price],MATCH(tblSales[[#This Row],[Product Code]],tblProducts[Product Code],0)),0) | G10: 1599 | H10: 12 | I10: =tblSales[[#This Row],[MRP]]*tblSales[[#This Row],[Quantity]] | J10: 0 | K10: 0.09 | L10: 0.09 | M10: 0 | N10: ="INV-"&tblSales[[#This Row],[Order Number]]
A11: HH_S000105 | B11: 46300 | C11: CUS-001 | D11: HH000101 | E11: =IFERROR(INDEX(tblProducts[Product Name],MATCH(tblSales[[#This Row],[Product Code]],tblProducts[Product Code],0)),"") | F11: =IFERROR(INDEX(tblProducts[Net Price],MATCH(tblSales[[#This Row],[Product Code]],tblProducts[Product Code],0)),0) | G11: 399 | H11: 12 | I11: =tblSales[[#This Row],[MRP]]*tblSales[[#This Row],[Quantity]] | J11: 0 | K11: 0.09 | L11: 0.09 | M11: 0 | N11: ="INV-"&tblSales[[#This Row],[Order Number]]
A12: HH_S000106 | B12: 46303 | C12: CUS-004 | D12: HH000103 | E12: =IFERROR(INDEX(tblProducts[Product Name],MATCH(tblSales[[#This Row],[Product Code]],tblProducts[Product Code],0)),"") | F12: =IFERROR(INDEX(tblProducts[Net Price],MATCH(tblSales[[#This Row],[Product Code]],tblProducts[Product Code],0)),0) | G12: 349 | H12: 24 | I12: =tblSales[[#This Row],[MRP]]*tblSales[[#This Row],[Quantity]] | J12: 0 | K12: 0 | L12: 0 | M12: 0.18 | N12: ="INV-"&tblSales[[#This Row],[Order Number]]

Sheet CUSTOMERS
A1: Happy Hatch – CUSTOMERS
A2: Blue = enter / edit. Sample rows are fictional - overwrite them with real records.
A4: Customer Number | B4: Customer Name | C4: Contact Person | D4: Phone | E4: Email | F4: Address | G4: City | H4: Remarks
A5: CUS-001 | B5: Sample Retail Traders | C5: Anita Rao | D5: 9000000001 | E5: anita@example.com | F5: 12 Market Road | G5: Chennai
A6: CUS-002 | B6: Sample Home Store | C6: Ravi Kumar | D6: 9000000002 | E6: ravi@example.com | F6: 45 Main Street | G6: Coimbatore
A7: CUS-003 | B7: Sample E-Commerce Seller | C7: Meena S | D7: 9000000003 | E7: meena@example.com | F7: 7 Tech Park | G7: Bengaluru
A8: CUS-004 | B8: Sample Stationery Mart | C8: John D | D8: 9000000004 | E8: john@example.com | F8: 3 College Lane | G8: Madurai

Sheet PURCHASE
A1: Happy Hatch – PURCHASE
A2: Blue = enter / edit. Product Code must exist in PRODUCTS (drop-down provided when typing in the grid). Product Name and Total Cost are calculated automatically.
A4: Purchase Number | B4: Date of Purchase | C4: Product Code | D4: Product Name | E4: Quantity | F4: Unit Cost | G4: Total Cost | H4: Shipper Name | I4: Shipper Contact | J4: Shipper Email | K4: Remarks
A5: PUR-001 | B5: 46270 | C5: HH000101 | D5: =IFERROR(INDEX(tblProducts[Product Name],MATCH(tblPurchase[[#This Row],[Product Code]],tblProducts[Product Code],0)),"") | E5: 120 | F5: 191 | G5: =tblPurchase[[#This Row],[Quantity]]*tblPurchase[[#This Row],[Unit Cost]] | H5: Sample Logistics | I5: 9200000001 | J5: dispatch@example.com
A6: PUR-002 | B6: 46270 | C6: HH000102 | D6: =IFERROR(INDEX(tblProducts[Product Name],MATCH(tblPurchase[[#This Row],[Product Code]],tblProducts[Product Code],0)),"") | E6: 60 | F6: 1108 | G6: =tblPurchase[[#This Row],[Quantity]]*tblPurchase[[#This Row],[Unit Cost]] | H6: Sample Logistics | I6: 9200000001 | J6: dispatch@example.com
A7: PUR-003 | B7: 46277 | C7: HH000103 | D7: =IFERROR(INDEX(tblProducts[Product Name],MATCH(tblPurchase[[#This Row],[Product Code]],tblProducts[Product Code],0)),"") | E7: 120 | F7: 183 | G7: =tblPurchase[[#This Row],[Quantity]]*tblPurchase[[#This Row],[Unit Cost]] | H7: Sample Logistics | I7: 9200000001 | J7: dispatch@example.com
A8: PUR-004 | B8: 46277 | C8: HH000104 | D8: =IFERROR(INDEX(tblProducts[Product Name],MATCH(tblPurchase[[#This Row],[Product Code]],tblProducts[Product Code],0)),"") | E8: 60 | F8: 1102 | G8: =tblPurchase[[#This Row],[Quantity]]*tblPurchase[[#This Row],[Unit Cost]] | H8: Sample Logistics | I8: 9200000001 | J8: dispatch@example.com
A9: PUR-005 | B9: 46285 | C9: HH000105 | D9: =IFERROR(INDEX(tblProducts[Product Name],MATCH(tblPurchase[[#This Row],[Product Code]],tblProducts[Product Code],0)),"") | E9: 340 | F9: 38 | G9: =tblPurchase[[#This Row],[Quantity]]*tblPurchase[[#This Row],[Unit Cost]] | H9: Sample Logistics | I9: 9200000001 | J9: dispatch@example.com
A10: PUR-006 | B10: 46290 | C10: HH000106 | D10: =IFERROR(INDEX(tblProducts[Product Name],MATCH(tblPurchase[[#This Row],[Product Code]],tblProducts[Product Code],0)),"") | E10: 50 | F10: 1870 | G10: =tblPurchase[[#This Row],[Quantity]]*tblPurchase[[#This Row],[Unit Cost]] | H10: Sample Logistics | I10: 9200000001 | J10: dispatch@example.com

Sheet INVOICE
A1: SALES INVOICE
A2: Pick an Order Number in the yellow cell: the invoice lists every product on that order. Print: File > Export > Create PDF (print area A1:G40, A4).
A4: Seller: | B4: Happy Hatch | F4: LOGO (insert logo here)
B5: Your address / GSTIN / phone
A7: Order Number | C7: HH_S000105 | D7: Invoice No. | F7: =IF($I$16="","","INV-"&$C$7)
D8: Invoice date | F8: =IF($I$16="","",INDEX(SALES!$B$5:$B$2000,$I$16))
D9: Customer No. | F9: =IF($I$16="","",INDEX(SALES!$C$5:$C$2000,$I$16))
A10: Bill to: | B10: =IFERROR(INDEX(CUSTOMERS!$B$5:$B$2000,MATCH($F$9,CUSTOMERS!$A$5:$A$2000,0)),"")
B11: =IFERROR(INDEX(CUSTOMERS!$F$5:$F$2000,MATCH($F$9,CUSTOMERS!$A$5:$A$2000,0)),"")
B12: =IFERROR(INDEX(CUSTOMERS!$G$5:$G$2000,MATCH($F$9,CUSTOMERS!$A$5:$A$2000,0)),"")
B13: =IFERROR("Phone: "&INDEX(CUSTOMERS!$D$5:$D2000,MATCH($F$9,CUSTOMERS!$A$5:$A2000,0)),"")
A15: S.No | B15: Order No. | C15: Product Code | D15: Product Name | E15: Qty | F15: MRP | G15: Amount | I15: helper | J15: row | K15: orders list (helper)
A16: =IF($I16="","",1) | B16: =IF($I16="","",INDEX(SALES!$A$5:$A$2000,$I16)) | C16: =IF($I16="","",INDEX(SALES!$D$5:$D$2000,$I16)) | D16: =IF($I16="","",INDEX(SALES!$E$5:$E$2000,$I16)) | E16: =IF($I16="","",INDEX(SALES!$H$5:$H$2000,$I16)) | F16: =IF($I16="","",INDEX(SALES!$G$5:$G$2000,$I16)) | G16: =IF($I16="","",INDEX(SALES!$I$5:$I$2000,$I16)) | I16: =IFERROR(IF(SUMPRODUCT(SMALL(((SALES!$A$5:$A$2000=$C$7)*(SALES!$A$5:$A$2000<>""))*(ROW(SALES!$A$5:$A$2000)-4)+(1-((SALES!$A$5:$A$2000=$C$7)*(SALES!$A$5:$A$2000<>"")))*1000000,1))>=1000000,"",SUMPRODUCT(SMALL(((SALES!$A$5:$A$2000=$C$7)*(SALES!$A$5:$A$2000<>""))*(ROW(SALES!$A$5:$A$2000)-4)+(1-((SALES!$A$5:$A$2000=$C$7)*(SALES!$A$5:$A$2000<>"")))*1000000,1))),"") | J16: =IFERROR(IF(SUMPRODUCT(SMALL(((SALES!$A$5:$A$2000<>"")*(COUNTIF($K$15:$K15,SALES!$A$5:$A$2000)=0))*(ROW(SALES!$A$5:$A$2000)-4)+(1-((SALES!$A$5:$A$2000<>"")*(COUNTIF($K$15:$K15,SALES!$A$5:$A$2000)=0)))*1000000,1))>=1000000,"",SUMPRODUCT(SMALL(((SALES!$A$5:$A$2000<>"")*(COUNTIF($K$15:$K15,SALES!$A$5:$A$2000)=0))*(ROW(SALES!$A$5:$A$2000)-4)+(1-((SALES!$A$5:$A$2000<>"")*(COUNTIF($K$15:$K15,SALES!$A$5:$A$2000)=0)))*1000000,1))),"") | K16: =IF($J16="","",INDEX(SALES!$A$5:$A$2000,$J16))
A17: =IF($I17="","",2) | B17: =IF($I17="","",INDEX(SALES!$A$5:$A$2000,$I17)) | C17: =IF($I17="","",INDEX(SALES!$D$5:$D$2000,$I17)) | D17: =IF($I17="","",INDEX(SALES!$E$5:$E$2000,$I17)) | E17: =IF($I17="","",INDEX(SALES!$H$5:$H$2000,$I17)) | F17: =IF($I17="","",INDEX(SALES!$G$5:$G$2000,$I17)) | G17: =IF($I17="","",INDEX(SALES!$I$5:$I$2000,$I17)) | I17: =IFERROR(IF(SUMPRODUCT(SMALL(((SALES!$A$5:$A$2000=$C$7)*(SALES!$A$5:$A$2000<>""))*(ROW(SALES!$A$5:$A$2000)-4)+(1-((SALES!$A$5:$A$2000=$C$7)*(SALES!$A$5:$A$2000<>"")))*1000000,2))>=1000000,"",SUMPRODUCT(SMALL(((SALES!$A$5:$A$2000=$C$7)*(SALES!$A$5:$A$2000<>""))*(ROW(SALES!$A$5:$A$2000)-4)+(1-((SALES!$A$5:$A$2000=$C$7)*(SALES!$A$5:$A$2000<>"")))*1000000,2))),"") | J17: =IFERROR(IF(SUMPRODUCT(SMALL(((SALES!$A$5:$A$2000<>"")*(COUNTIF($K$15:$K16,SALES!$A$5:$A$2000)=0))*(ROW(SALES!$A$5:$A$2000)-4)+(1-((SALES!$A$5:$A$2000<>"")*(COUNTIF($K$15:$K16,SALES!$A$5:$A$2000)=0)))*1000000,1))>=1000000,"",SUMPRODUCT(SMALL(((SALES!$A$5:$A$2000<>"")*(COUNTIF($K$15:$K16,SALES!$A$5:$A$2000)=0))*(ROW(SALES!$A$5:$A$2000)-4)+(1-((SALES!$A$5:$A$2000<>"")*(COUNTIF($K$15:$K16,SALES!$A$5:$A$2000)=0)))*1000000,1))),"") | K17: =IF($J17="","",INDEX(SALES!$A$5:$A$2000,$J17))
A18: =IF($I18="","",3) | B18: =IF($I18="","",INDEX(SALES!$A$5:$A$2000,$I18)) | C18: =IF($I18="","",INDEX(SALES!$D$5:$D$2000,$I18)) | D18: =IF($I18="","",INDEX(SALES!$E$5:$E$2000,$I18)) | E18: =IF($I18="","",INDEX(SALES!$H$5:$H$2000,$I18)) | F18: =IF($I18="","",INDEX(SALES!$G$5:$G$2000,$I18)) | G18: =IF($I18="","",INDEX(SALES!$I$5:$I$2000,$I18)) | I18: =IFERROR(IF(SUMPRODUCT(SMALL(((SALES!$A$5:$A$2000=$C$7)*(SALES!$A$5:$A$2000<>""))*(ROW(SALES!$A$5:$A$2000)-4)+(1-((SALES!$A$5:$A$2000=$C$7)*(SALES!$A$5:$A$2000<>"")))*1000000,3))>=1000000,"",SUMPRODUCT(SMALL(((SALES!$A$5:$A$2000=$C$7)*(SALES!$A$5:$A$2000<>""))*(ROW(SALES!$A$5:$A$2000)-4)+(1-((SALES!$A$5:$A$2000=$C$7)*(SALES!$A$5:$A$2000<>"")))*1000000,3))),"") | J18: =IFERROR(IF(SUMPRODUCT(SMALL(((SALES!$A$5:$A$2000<>"")*(COUNTIF($K$15:$K17,SALES!$A$5:$A$2000)=0))*(ROW(SALES!$A$5:$A$2000)-4)+(1-((SALES!$A$5:$A$2000<>"")*(COUNTIF($K$15:$K17,SALES!$A$5:$A$2000)=0)))*1000000,1))>=1000000,"",SUMPRODUCT(SMALL(((SALES!$A$5:$A$2000<>"")*(COUNTIF($K$15:$K17,SALES!$A$5:$A$2000)=0))*(ROW(SALES!$A$5:$A$2000)-4)+(1-((SALES!$A$5:$A$2000<>"")*(COUNTIF($K$15:$K17,SALES!$A$5:$A$2000)=0)))*1000000,1))),"") | K18: =IF($J18="","",INDEX(SALES!$A$5:$A$2000,$J18))
A19: =IF($I19="","",4) | B19: =IF($I19="","",INDEX(SALES!$A$5:$A$2000,$I19)) | C19: =IF($I19="","",INDEX(SALES!$D$5:$D$2000,$I19)) | D19: =IF($I19="","",INDEX(SALES!$E$5:$E$2000,$I19)) | E19: =IF($I19="","",INDEX(SALES!$H$5:$H$2000,$I19)) | F19: =IF($I19="","",INDEX(SALES!$G$5:$G$2000,$I19)) | G19: =IF($I19="","",INDEX(SALES!$I$5:$I$2000,$I19)) | I19: =IFERROR(IF(SUMPRODUCT(SMALL(((SALES!$A$5:$A$2000=$C$7)*(SALES!$A$5:$A$2000<>""))*(ROW(SALES!$A$5:$A$2000)-4)+(1-((SALES!$A$5:$A$2000=$C$7)*(SALES!$A$5:$A$2000<>"")))*1000000,4))>=1000000,"",SUMPRODUCT(SMALL(((SALES!$A$5:$A$2000=$C$7)*(SALES!$A$5:$A$2000<>""))*(ROW(SALES!$A$5:$A$2000)-4)+(1-((SALES!$A$5:$A$2000=$C$7)*(SALES!$A$5:$A$2000<>"")))*1000000,4))),"") | J19: =IFERROR(IF(SUMPRODUCT(SMALL(((SALES!$A$5:$A$2000<>"")*(COUNTIF($K$15:$K18,SALES!$A$5:$A$2000)=0))*(ROW(SALES!$A$5:$A$2000)-4)+(1-((SALES!$A$5:$A$2000<>"")*(COUNTIF($K$15:$K18,SALES!$A$5:$A$2000)=0)))*1000000,1))>=1000000,"",SUMPRODUCT(SMALL(((SALES!$A$5:$A$2000<>"")*(COUNTIF($K$15:$K18,SALES!$A$5:$A$2000)=0))*(ROW(SALES!$A$5:$A$2000)-4)+(1-((SALES!$A$5:$A$2000<>"")*(COUNTIF($K$15:$K18,SALES!$A$5:$A$2000)=0)))*1000000,1))),"") | K19: =IF($J19="","",INDEX(SALES!$A$5:$A$2000,$J19))
A20: =IF($I20="","",5) | B20: =IF($I20="","",INDEX(SALES!$A$5:$A$2000,$I20)) | C20: =IF($I20="","",INDEX(SALES!$D$5:$D$2000,$I20)) | D20: =IF($I20="","",INDEX(SALES!$E$5:$E$2000,$I20)) | E20: =IF($I20="","",INDEX(SALES!$H$5:$H$2000,$I20)) | F20: =IF($I20="","",INDEX(SALES!$G$5:$G$2000,$I20)) | G20: =IF($I20="","",INDEX(SALES!$I$5:$I$2000,$I20)) | I20: =IFERROR(IF(SUMPRODUCT(SMALL(((SALES!$A$5:$A$2000=$C$7)*(SALES!$A$5:$A$2000<>""))*(ROW(SALES!$A$5:$A$2000)-4)+(1-((SALES!$A$5:$A$2000=$C$7)*(SALES!$A$5:$A$2000<>"")))*1000000,5))>=1000000,"",SUMPRODUCT(SMALL(((SALES!$A$5:$A$2000=$C$7)*(SALES!$A$5:$A$2000<>""))*(ROW(SALES!$A$5:$A$2000)-4)+(1-((SALES!$A$5:$A$2000=$C$7)*(SALES!$A$5:$A$2000<>"")))*1000000,5))),"") | J20: =IFERROR(IF(SUMPRODUCT(SMALL(((SALES!$A$5:$A$2000<>"")*(COUNTIF($K$15:$K19,SALES!$A$5:$A$2000)=0))*(ROW(SALES!$A$5:$A$2000)-4)+(1-((SALES!$A$5:$A$2000<>"")*(COUNTIF($K$15:$K19,SALES!$A$5:$A$2000)=0)))*1000000,1))>=1000000,"",SUMPRODUCT(SMALL(((SALES!$A$5:$A$2000<>"")*(COUNTIF($K$15:$K19,SALES!$A$5:$A$2000)=0))*(ROW(SALES!$A$5:$A$2000)-4)+(1-((SALES!$A$5:$A$2000<>"")*(COUNTIF($K$15:$K19,SALES!$A$5:$A$2000)=0)))*1000000,1))),"") | K20: =IF($J20="","",INDEX(SALES!$A$5:$A$2000,$J20))
A21: =IF($I21="","",6) | B21: =IF($I21="","",INDEX(SALES!$A$5:$A$2000,$I21)) | C21: =IF($I21="","",INDEX(SALES!$D$5:$D$2000,$I21)) | D21: =IF($I21="","",INDEX(SALES!$E$5:$E$2000,$I21)) | E21: =IF($I21="","",INDEX(SALES!$H$5:$H$2000,$I21)) | F21: =IF($I21="","",INDEX(SALES!$G$5:$G$2000,$I21)) | G21: =IF($I21="","",INDEX(SALES!$I$5:$I$2000,$I21)) | I21: =IFERROR(IF(SUMPRODUCT(SMALL(((SALES!$A$5:$A$2000=$C$7)*(SALES!$A$5:$A$2000<>""))*(ROW(SALES!$A$5:$A$2000)-4)+(1-((SALES!$A$5:$A$2000=$C$7)*(SALES!$A$5:$A$2000<>"")))*1000000,6))>=1000000,"",SUMPRODUCT(SMALL(((SALES!$A$5:$A$2000=$C$7)*(SALES!$A$5:$A$2000<>""))*(ROW(SALES!$A$5:$A$2000)-4)+(1-((SALES!$A$5:$A$2000=$C$7)*(SALES!$A$5:$A$2000<>"")))*1000000,6))),"") | J21: =IFERROR(IF(SUMPRODUCT(SMALL(((SALES!$A$5:$A$2000<>"")*(COUNTIF($K$15:$K20,SALES!$A$5:$A$2000)=0))*(ROW(SALES!$A$5:$A$2000)-4)+(1-((SALES!$A$5:$A$2000<>"")*(COUNTIF($K$15:$K20,SALES!$A$5:$A$2000)=0)))*1000000,1))>=1000000,"",SUMPRODUCT(SMALL(((SALES!$A$5:$A$2000<>"")*(COUNTIF($K$15:$K20,SALES!$A$5:$A$2000)=0))*(ROW(SALES!$A$5:$A$2000)-4)+(1-((SALES!$A$5:$A$2000<>"")*(COUNTIF($K$15:$K20,SALES!$A$5:$A$2000)=0)))*1000000,1))),"") | K21: =IF($J21="","",INDEX(SALES!$A$5:$A$2000,$J21))
A22: =IF($I22="","",7) | B22: =IF($I22="","",INDEX(SALES!$A$5:$A$2000,$I22)) | C22: =IF($I22="","",INDEX(SALES!$D$5:$D$2000,$I22)) | D22: =IF($I22="","",INDEX(SALES!$E$5:$E$2000,$I22)) | E22: =IF($I22="","",INDEX(SALES!$H$5:$H$2000,$I22)) | F22: =IF($I22="","",INDEX(SALES!$G$5:$G$2000,$I22)) | G22: =IF($I22="","",INDEX(SALES!$I$5:$I$2000,$I22)) | I22: =IFERROR(IF(SUMPRODUCT(SMALL(((SALES!$A$5:$A$2000=$C$7)*(SALES!$A$5:$A$2000<>""))*(ROW(SALES!$A$5:$A$2000)-4)+(1-((SALES!$A$5:$A$2000=$C$7)*(SALES!$A$5:$A$2000<>"")))*1000000,7))>=1000000,"",SUMPRODUCT(SMALL(((SALES!$A$5:$A$2000=$C$7)*(SALES!$A$5:$A$2000<>""))*(ROW(SALES!$A$5:$A$2000)-4)+(1-((SALES!$A$5:$A$2000=$C$7)*(SALES!$A$5:$A$2000<>"")))*1000000,7))),"") | J22: =IFERROR(IF(SUMPRODUCT(SMALL(((SALES!$A$5:$A$2000<>"")*(COUNTIF($K$15:$K21,SALES!$A$5:$A$2000)=0))*(ROW(SALES!$A$5:$A$2000)-4)+(1-((SALES!$A$5:$A$2000<>"")*(COUNTIF($K$15:$K21,SALES!$A$5:$A$2000)=0)))*1000000,1))>=1000000,"",SUMPRODUCT(SMALL(((SALES!$A$5:$A$2000<>"")*(COUNTIF($K$15:$K21,SALES!$A$5:$A$2000)=0))*(ROW(SALES!$A$5:$A$2000)-4)+(1-((SALES!$A$5:$A$2000<>"")*(COUNTIF($K$15:$K21,SALES!$A$5:$A$2000)=0)))*1000000,1))),"") | K22: =IF($J22="","",INDEX(SALES!$A$5:$A$2000,$J22))
A23: =IF($I23="","",8) | B23: =IF($I23="","",INDEX(SALES!$A$5:$A$2000,$I23)) | C23: =IF($I23="","",INDEX(SALES!$D$5:$D$2000,$I23)) | D23: =IF($I23="","",INDEX(SALES!$E$5:$E$2000,$I23)) | E23: =IF($I23="","",INDEX(SALES!$H$5:$H$2000,$I23)) | F23: =IF($I23="","",INDEX(SALES!$G$5:$G$2000,$I23)) | G23: =IF($I23="","",INDEX(SALES!$I$5:$I$2000,$I23)) | I23: =IFERROR(IF(SUMPRODUCT(SMALL(((SALES!$A$5:$A$2000=$C$7)*(SALES!$A$5:$A$2000<>""))*(ROW(SALES!$A$5:$A$2000)-4)+(1-((SALES!$A$5:$A$2000=$C$7)*(SALES!$A$5:$A$2000<>"")))*1000000,8))>=1000000,"",SUMPRODUCT(SMALL(((SALES!$A$5:$A$2000=$C$7)*(SALES!$A$5:$A$2000<>""))*(ROW(SALES!$A$5:$A$2000)-4)+(1-((SALES!$A$5:$A$2000=$C$7)*(SALES!$A$5:$A$2000<>"")))*1000000,8))),"") | J23: =IFERROR(IF(SUMPRODUCT(SMALL(((SALES!$A$5:$A$2000<>"")*(COUNTIF($K$15:$K22,SALES!$A$5:$A$2000)=0))*(ROW(SALES!$A$5:$A$2000)-4)+(1-((SALES!$A$5:$A$2000<>"")*(COUNTIF($K$15:$K22,SALES!$A$5:$A$2000)=0)))*1000000,1))>=1000000,"",SUMPRODUCT(SMALL(((SALES!$A$5:$A$2000<>"")*(COUNTIF($K$15:$K22,SALES!$A$5:$A$2000)=0))*(ROW(SALES!$A$5:$A$2000)-4)+(1-((SALES!$A$5:$A$2000<>"")*(COUNTIF($K$15:$K22,SALES!$A$5:$A$2000)=0)))*1000000,1))),"") | K23: =IF($J23="","",INDEX(SALES!$A$5:$A$2000,$J23))
A24: =IF($I24="","",9) | B24: =IF($I24="","",INDEX(SALES!$A$5:$A$2000,$I24)) | C24: =IF($I24="","",INDEX(SALES!$D$5:$D$2000,$I24)) | D24: =IF($I24="","",INDEX(SALES!$E$5:$E$2000,$I24)) | E24: =IF($I24="","",INDEX(SALES!$H$5:$H$2000,$I24)) | F24: =IF($I24="","",INDEX(SALES!$G$5:$G$2000,$I24)) | G24: =IF($I24="","",INDEX(SALES!$I$5:$I$2000,$I24)) | I24: =IFERROR(IF(SUMPRODUCT(SMALL(((SALES!$A$5:$A$2000=$C$7)*(SALES!$A$5:$A$2000<>""))*(ROW(SALES!$A$5:$A$2000)-4)+(1-((SALES!$A$5:$A$2000=$C$7)*(SALES!$A$5:$A$2000<>"")))*1000000,9))>=1000000,"",SUMPRODUCT(SMALL(((SALES!$A$5:$A$2000=$C$7)*(SALES!$A$5:$A$2000<>""))*(ROW(SALES!$A$5:$A$2000)-4)+(1-((SALES!$A$5:$A$2000=$C$7)*(SALES!$A$5:$A$2000<>"")))*1000000,9))),"") | J24: =IFERROR(IF(SUMPRODUCT(SMALL(((SALES!$A$5:$A$2000<>"")*(COUNTIF($K$15:$K23,SALES!$A$5:$A$2000)=0))*(ROW(SALES!$A$5:$A$2000)-4)+(1-((SALES!$A$5:$A$2000<>"")*(COUNTIF($K$15:$K23,SALES!$A$5:$A$2000)=0)))*1000000,1))>=1000000,"",SUMPRODUCT(SMALL(((SALES!$A$5:$A$2000<>"")*(COUNTIF($K$15:$K23,SALES!$A$5:$A$2000)=0))*(ROW(SALES!$A$5:$A$2000)-4)+(1-((SALES!$A$5:$A$2000<>"")*(COUNTIF($K$15:$K23,SALES!$A$5:$A$2000)=0)))*1000000,1))),"") | K24: =IF($J24="","",INDEX(SALES!$A$5:$A$2000,$J24))
A25: =IF($I25="","",10) | B25: =IF($I25="","",INDEX(SALES!$A$5:$A$2000,$I25)) | C25: =IF($I25="","",INDEX(SALES!$D$5:$D$2000,$I25)) | D25: =IF($I25="","",INDEX(SALES!$E$5:$E$2000,$I25)) | E25: =IF($I25="","",INDEX(SALES!$H$5:$H$2000,$I25)) | F25: =IF($I25="","",INDEX(SALES!$G$5:$G$2000,$I25)) | G25: =IF($I25="","",INDEX(SALES!$I$5:$I$2000,$I25)) | I25: =IFERROR(IF(SUMPRODUCT(SMALL(((SALES!$A$5:$A$2000=$C$7)*(SALES!$A$5:$A$2000<>""))*(ROW(SALES!$A$5:$A$2000)-4)+(1-((SALES!$A$5:$A$2000=$C$7)*(SALES!$A$5:$A$2000<>"")))*1000000,10))>=1000000,"",SUMPRODUCT(SMALL(((SALES!$A$5:$A$2000=$C$7)*(SALES!$A$5:$A$2000<>""))*(ROW(SALES!$A$5:$A$2000)-4)+(1-((SALES!$A$5:$A$2000=$C$7)*(SALES!$A$5:$A$2000<>"")))*1000000,10))),"") | J25: =IFERROR(IF(SUMPRODUCT(SMALL(((SALES!$A$5:$A$2000<>"")*(COUNTIF($K$15:$K24,SALES!$A$5:$A$2000)=0))*(ROW(SALES!$A$5:$A$2000)-4)+(1-((SALES!$A$5:$A$2000<>"")*(COUNTIF($K$15:$K24,SALES!$A$5:$A$2000)=0)))*1000000,1))>=1000000,"",SUMPRODUCT(SMALL(((SALES!$A$5:$A$2000<>"")*(COUNTIF($K$15:$K24,SALES!$A$5:$A$2000)=0))*(ROW(SALES!$A$5:$A$2000)-4)+(1-((SALES!$A$5:$A$2000<>"")*(COUNTIF($K$15:$K24,SALES!$A$5:$A$2000)=0)))*1000000,1))),"") | K25: =IF($J25="","",INDEX(SALES!$A$5:$A$2000,$J25))
A26: =IF($I26="","",11) | B26: =IF($I26="","",INDEX(SALES!$A$5:$A$2000,$I26)) | C26: =IF($I26="","",INDEX(SALES!$D$5:$D$2000,$I26)) | D26: =IF($I26="","",INDEX(SALES!$E$5:$E$2000,$I26)) | E26: =IF($I26="","",INDEX(SALES!$H$5:$H$2000,$I26)) | F26: =IF($I26="","",INDEX(SALES!$G$5:$G$2000,$I26)) | G26: =IF($I26="","",INDEX(SALES!$I$5:$I$2000,$I26)) | I26: =IFERROR(IF(SUMPRODUCT(SMALL(((SALES!$A$5:$A$2000=$C$7)*(SALES!$A$5:$A$2000<>""))*(ROW(SALES!$A$5:$A$2000)-4)+(1-((SALES!$A$5:$A$2000=$C$7)*(SALES!$A$5:$A$2000<>"")))*1000000,11))>=1000000,"",SUMPRODUCT(SMALL(((SALES!$A$5:$A$2000=$C$7)*(SALES!$A$5:$A$2000<>""))*(ROW(SALES!$A$5:$A$2000)-4)+(1-((SALES!$A$5:$A$2000=$C$7)*(SALES!$A$5:$A$2000<>"")))*1000000,11))),"") | J26: =IFERROR(IF(SUMPRODUCT(SMALL(((SALES!$A$5:$A$2000<>"")*(COUNTIF($K$15:$K25,SALES!$A$5:$A$2000)=0))*(ROW(SALES!$A$5:$A$2000)-4)+(1-((SALES!$A$5:$A$2000<>"")*(COUNTIF($K$15:$K25,SALES!$A$5:$A$2000)=0)))*1000000,1))>=1000000,"",SUMPRODUCT(SMALL(((SALES!$A$5:$A$2000<>"")*(COUNTIF($K$15:$K25,SALES!$A$5:$A$2000)=0))*(ROW(SALES!$A$5:$A$2000)-4)+(1-((SALES!$A$5:$A$2000<>"")*(COUNTIF($K$15:$K25,SALES!$A$5:$A$2000)=0)))*1000000,1))),"") | K26: =IF($J26="","",INDEX(SALES!$A$5:$A$2000,$J26))
A27: =IF($I27="","",12) | B27: =IF($I27="","",INDEX(SALES!$A$5:$A$2000,$I27)) | C27: =IF($I27="","",INDEX(SALES!$D$5:$D$2000,$I27)) | D27: =IF($I27="","",INDEX(SALES!$E$5:$E$2000,$I27)) | E27: =IF($I27="","",INDEX(SALES!$H$5:$H$2000,$I27)) | F27: =IF($I27="","",INDEX(SALES!$G$5:$G$2000,$I27)) | G27: =IF($I27="","",INDEX(SALES!$I$5:$I$2000,$I27)) | I27: =IFERROR(IF(SUMPRODUCT(SMALL(((SALES!$A$5:$A$2000=$C$7)*(SALES!$A$5:$A$2000<>""))*(ROW(SALES!$A$5:$A$2000)-4)+(1-((SALES!$A$5:$A$2000=$C$7)*(SALES!$A$5:$A$2000<>"")))*1000000,12))>=1000000,"",SUMPRODUCT(SMALL(((SALES!$A$5:$A$2000=$C$7)*(SALES!$A$5:$A$2000<>""))*(ROW(SALES!$A$5:$A$2000)-4)+(1-((SALES!$A$5:$A$2000=$C$7)*(SALES!$A$5:$A$2000<>"")))*1000000,12))),"") | J27: =IFERROR(IF(SUMPRODUCT(SMALL(((SALES!$A$5:$A$2000<>"")*(COUNTIF($K$15:$K26,SALES!$A$5:$A$2000)=0))*(ROW(SALES!$A$5:$A$2000)-4)+(1-((SALES!$A$5:$A$2000<>"")*(COUNTIF($K$15:$K26,SALES!$A$5:$A$2000)=0)))*1000000,1))>=1000000,"",SUMPRODUCT(SMALL(((SALES!$A$5:$A$2000<>"")*(COUNTIF($K$15:$K26,SALES!$A$5:$A$2000)=0))*(ROW(SALES!$A$5:$A$2000)-4)+(1-((SALES!$A$5:$A$2000<>"")*(COUNTIF($K$15:$K26,SALES!$A$5:$A$2000)=0)))*1000000,1))),"") | K27: =IF($J27="","",INDEX(SALES!$A$5:$A$2000,$J27))
A28: =IF($I28="","",13) | B28: =IF($I28="","",INDEX(SALES!$A$5:$A$2000,$I28)) | C28: =IF($I28="","",INDEX(SALES!$D$5:$D$2000,$I28)) | D28: =IF($I28="","",INDEX(SALES!$E$5:$E$2000,$I28)) | E28: =IF($I28="","",INDEX(SALES!$H$5:$H$2000,$I28)) | F28: =IF($I28="","",INDEX(SALES!$G$5:$G$2000,$I28)) | G28: =IF($I28="","",INDEX(SALES!$I$5:$I$2000,$I28)) | I28: =IFERROR(IF(SUMPRODUCT(SMALL(((SALES!$A$5:$A$2000=$C$7)*(SALES!$A$5:$A$2000<>""))*(ROW(SALES!$A$5:$A$2000)-4)+(1-((SALES!$A$5:$A$2000=$C$7)*(SALES!$A$5:$A$2000<>"")))*1000000,13))>=1000000,"",SUMPRODUCT(SMALL(((SALES!$A$5:$A$2000=$C$7)*(SALES!$A$5:$A$2000<>""))*(ROW(SALES!$A$5:$A$2000)-4)+(1-((SALES!$A$5:$A$2000=$C$7)*(SALES!$A$5:$A$2000<>"")))*1000000,13))),"") | J28: =IFERROR(IF(SUMPRODUCT(SMALL(((SALES!$A$5:$A$2000<>"")*(COUNTIF($K$15:$K27,SALES!$A$5:$A$2000)=0))*(ROW(SALES!$A$5:$A$2000)-4)+(1-((SALES!$A$5:$A$2000<>"")*(COUNTIF($K$15:$K27,SALES!$A$5:$A$2000)=0)))*1000000,1))>=1000000,"",SUMPRODUCT(SMALL(((SALES!$A$5:$A$2000<>"")*(COUNTIF($K$15:$K27,SALES!$A$5:$A$2000)=0))*(ROW(SALES!$A$5:$A$2000)-4)+(1-((SALES!$A$5:$A$2000<>"")*(COUNTIF($K$15:$K27,SALES!$A$5:$A$2000)=0)))*1000000,1))),"") | K28: =IF($J28="","",INDEX(SALES!$A$5:$A$2000,$J28))
A29: =IF($I29="","",14) | B29: =IF($I29="","",INDEX(SALES!$A$5:$A$2000,$I29)) | C29: =IF($I29="","",INDEX(SALES!$D$5:$D$2000,$I29)) | D29: =IF($I29="","",INDEX(SALES!$E$5:$E$2000,$I29)) | E29: =IF($I29="","",INDEX(SALES!$H$5:$H$2000,$I29)) | F29: =IF($I29="","",INDEX(SALES!$G$5:$G$2000,$I29)) | G29: =IF($I29="","",INDEX(SALES!$I$5:$I$2000,$I29)) | I29: =IFERROR(IF(SUMPRODUCT(SMALL(((SALES!$A$5:$A$2000=$C$7)*(SALES!$A$5:$A$2000<>""))*(ROW(SALES!$A$5:$A$2000)-4)+(1-((SALES!$A$5:$A$2000=$C$7)*(SALES!$A$5:$A$2000<>"")))*1000000,14))>=1000000,"",SUMPRODUCT(SMALL(((SALES!$A$5:$A$2000=$C$7)*(SALES!$A$5:$A$2000<>""))*(ROW(SALES!$A$5:$A$2000)-4)+(1-((SALES!$A$5:$A$2000=$C$7)*(SALES!$A$5:$A$2000<>"")))*1000000,14))),"") | J29: =IFERROR(IF(SUMPRODUCT(SMALL(((SALES!$A$5:$A$2000<>"")*(COUNTIF($K$15:$K28,SALES!$A$5:$A$2000)=0))*(ROW(SALES!$A$5:$A$2000)-4)+(1-((SALES!$A$5:$A$2000<>"")*(COUNTIF($K$15:$K28,SALES!$A$5:$A$2000)=0)))*1000000,1))>=1000000,"",SUMPRODUCT(SMALL(((SALES!$A$5:$A$2000<>"")*(COUNTIF($K$15:$K28,SALES!$A$5:$A$2000)=0))*(ROW(SALES!$A$5:$A$2000)-4)+(1-((SALES!$A$5:$A$2000<>"")*(COUNTIF($K$15:$K28,SALES!$A$5:$A$2000)=0)))*1000000,1))),"") | K29: =IF($J29="","",INDEX(SALES!$A$5:$A$2000,$J29))
A30: =IF($I30="","",15) | B30: =IF($I30="","",INDEX(SALES!$A$5:$A$2000,$I30)) | C30: =IF($I30="","",INDEX(SALES!$D$5:$D$2000,$I30)) | D30: =IF($I30="","",INDEX(SALES!$E$5:$E$2000,$I30)) | E30: =IF($I30="","",INDEX(SALES!$H$5:$H$2000,$I30)) | F30: =IF($I30="","",INDEX(SALES!$G$5:$G$2000,$I30)) | G30: =IF($I30="","",INDEX(SALES!$I$5:$I$2000,$I30)) | I30: =IFERROR(IF(SUMPRODUCT(SMALL(((SALES!$A$5:$A$2000=$C$7)*(SALES!$A$5:$A$2000<>""))*(ROW(SALES!$A$5:$A$2000)-4)+(1-((SALES!$A$5:$A$2000=$C$7)*(SALES!$A$5:$A$2000<>"")))*1000000,15))>=1000000,"",SUMPRODUCT(SMALL(((SALES!$A$5:$A$2000=$C$7)*(SALES!$A$5:$A$2000<>""))*(ROW(SALES!$A$5:$A$2000)-4)+(1-((SALES!$A$5:$A$2000=$C$7)*(SALES!$A$5:$A$2000<>"")))*1000000,15))),"") | J30: =IFERROR(IF(SUMPRODUCT(SMALL(((SALES!$A$5:$A$2000<>"")*(COUNTIF($K$15:$K29,SALES!$A$5:$A$2000)=0))*(ROW(SALES!$A$5:$A$2000)-4)+(1-((SALES!$A$5:$A$2000<>"")*(COUNTIF($K$15:$K29,SALES!$A$5:$A$2000)=0)))*1000000,1))>=1000000,"",SUMPRODUCT(SMALL(((SALES!$A$5:$A$2000<>"")*(COUNTIF($K$15:$K29,SALES!$A$5:$A$2000)=0))*(ROW(SALES!$A$5:$A$2000)-4)+(1-((SALES!$A$5:$A$2000<>"")*(COUNTIF($K$15:$K29,SALES!$A$5:$A$2000)=0)))*1000000,1))),"") | K30: =IF($J30="","",INDEX(SALES!$A$5:$A$2000,$J30))
J31: =IFERROR(IF(SUMPRODUCT(SMALL(((SALES!$A$5:$A$2000<>"")*(COUNTIF($K$15:$K30,SALES!$A$5:$A$2000)=0))*(ROW(SALES!$A$5:$A$2000)-4)+(1-((SALES!$A$5:$A$2000<>"")*(COUNTIF($K$15:$K30,SALES!$A$5:$A$2000)=0)))*1000000,1))>=1000000,"",SUMPRODUCT(SMALL(((SALES!$A$5:$A$2000<>"")*(COUNTIF($K$15:$K30,SALES!$A$5:$A$2000)=0))*(ROW(SALES!$A$5:$A$2000)-4)+(1-((SALES!$A$5:$A$2000<>"")*(COUNTIF($K$15:$K30,SALES!$A$5:$A$2000)=0)))*1000000,1))),"") | K31: =IF($J31="","",INDEX(SALES!$A$5:$A$2000,$J31))
F32: Subtotal | G32: =SUM(G16:G30) | J32: =IFERROR(IF(SUMPRODUCT(SMALL(((SALES!$A$5:$A$2000<>"")*(COUNTIF($K$15:$K31,SALES!$A$5:$A$2000)=0))*(ROW(SALES!$A$5:$A$2000)-4)+(1-((SALES!$A$5:$A$2000<>"")*(COUNTIF($K$15:$K31,SALES!$A$5:$A$2000)=0)))*1000000,1))>=1000000,"",SUMPRODUCT(SMALL(((SALES!$A$5:$A$2000<>"")*(COUNTIF($K$15:$K31,SALES!$A$5:$A$2000)=0))*(ROW(SALES!$A$5:$A$2000)-4)+(1-((SALES!$A$5:$A$2000<>"")*(COUNTIF($K$15:$K31,SALES!$A$5:$A$2000)=0)))*1000000,1))),"") | K32: =IF($J32="","",INDEX(SALES!$A$5:$A$2000,$J32))
F33: ="GST ("&ROUND(IF($I$16="",0,INDEX(SALES!$J$5:$J$2000,$I$16))*100,2)&"%)" | G33: =$G$32*IF($I$16="",0,INDEX(SALES!$J$5:$J$2000,$I$16)) | J33: =IFERROR(IF(SUMPRODUCT(SMALL(((SALES!$A$5:$A$2000<>"")*(COUNTIF($K$15:$K32,SALES!$A$5:$A$2000)=0))*(ROW(SALES!$A$5:$A$2000)-4)+(1-((SALES!$A$5:$A$2000<>"")*(COUNTIF($K$15:$K32,SALES!$A$5:$A$2000)=0)))*1000000,1))>=1000000,"",SUMPRODUCT(SMALL(((SALES!$A$5:$A$2000<>"")*(COUNTIF($K$15:$K32,SALES!$A$5:$A$2000)=0))*(ROW(SALES!$A$5:$A$2000)-4)+(1-((SALES!$A$5:$A$2000<>"")*(COUNTIF($K$15:$K32,SALES!$A$5:$A$2000)=0)))*1000000,1))),"") | K33: =IF($J33="","",INDEX(SALES!$A$5:$A$2000,$J33))
F34: ="CGST ("&ROUND(IF($I$16="",0,INDEX(SALES!$K$5:$K$2000,$I$16))*100,2)&"%)" | G34: =$G$32*IF($I$16="",0,INDEX(SALES!$K$5:$K$2000,$I$16)) | J34: =IFERROR(IF(SUMPRODUCT(SMALL(((SALES!$A$5:$A$2000<>"")*(COUNTIF($K$15:$K33,SALES!$A$5:$A$2000)=0))*(ROW(SALES!$A$5:$A$2000)-4)+(1-((SALES!$A$5:$A$2000<>"")*(COUNTIF($K$15:$K33,SALES!$A$5:$A$2000)=0)))*1000000,1))>=1000000,"",SUMPRODUCT(SMALL(((SALES!$A$5:$A$2000<>"")*(COUNTIF($K$15:$K33,SALES!$A$5:$A$2000)=0))*(ROW(SALES!$A$5:$A$2000)-4)+(1-((SALES!$A$5:$A$2000<>"")*(COUNTIF($K$15:$K33,SALES!$A$5:$A$2000)=0)))*1000000,1))),"") | K34: =IF($J34="","",INDEX(SALES!$A$5:$A$2000,$J34))
F35: ="SGST ("&ROUND(IF($I$16="",0,INDEX(SALES!$L$5:$L$2000,$I$16))*100,2)&"%)" | G35: =$G$32*IF($I$16="",0,INDEX(SALES!$L$5:$L$2000,$I$16)) | J35: =IFERROR(IF(SUMPRODUCT(SMALL(((SALES!$A$5:$A$2000<>"")*(COUNTIF($K$15:$K34,SALES!$A$5:$A$2000)=0))*(ROW(SALES!$A$5:$A$2000)-4)+(1-((SALES!$A$5:$A$2000<>"")*(COUNTIF($K$15:$K34,SALES!$A$5:$A$2000)=0)))*1000000,1))>=1000000,"",SUMPRODUCT(SMALL(((SALES!$A$5:$A$2000<>"")*(COUNTIF($K$15:$K34,SALES!$A$5:$A$2000)=0))*(ROW(SALES!$A$5:$A$2000)-4)+(1-((SALES!$A$5:$A$2000<>"")*(COUNTIF($K$15:$K34,SALES!$A$5:$A$2000)=0)))*1000000,1))),"") | K35: =IF($J35="","",INDEX(SALES!$A$5:$A$2000,$J35))
F36: ="IGST ("&ROUND(IF($I$16="",0,INDEX(SALES!$M$5:$M$2000,$I$16))*100,2)&"%)" | G36: =$G$32*IF($I$16="",0,INDEX(SALES!$M$5:$M$2000,$I$16)) | J36: =IFERROR(IF(SUMPRODUCT(SMALL(((SALES!$A$5:$A$2000<>"")*(COUNTIF($K$15:$K35,SALES!$A$5:$A$2000)=0))*(ROW(SALES!$A$5:$A$2000)-4)+(1-((SALES!$A$5:$A$2000<>"")*(COUNTIF($K$15:$K35,SALES!$A$5:$A$2000)=0)))*1000000,1))>=1000000,"",SUMPRODUCT(SMALL(((SALES!$A$5:$A$2000<>"")*(COUNTIF($K$15:$K35,SALES!$A$5:$A$2000)=0))*(ROW(SALES!$A$5:$A$2000)-4)+(1-((SALES!$A$5:$A$2000<>"")*(COUNTIF($K$15:$K35,SALES!$A$5:$A$2000)=0)))*1000000,1))),"") | K36: =IF($J36="","",INDEX(SALES!$A$5:$A$2000,$J36))
F37: TOTAL | G37: =G32+G33+G34+G35+G36 | J37: =IFERROR(IF(SUMPRODUCT(SMALL(((SALES!$A$5:$A$2000<>"")*(COUNTIF($K$15:$K36,SALES!$A$5:$A$2000)=0))*(ROW(SALES!$A$5:$A$2000)-4)+(1-((SALES!$A$5:$A$2000<>"")*(COUNTIF($K$15:$K36,SALES!$A$5:$A$2000)=0)))*1000000,1))>=1000000,"",SUMPRODUCT(SMALL(((SALES!$A$5:$A$2000<>"")*(COUNTIF($K$15:$K36,SALES!$A$5:$A$2000)=0))*(ROW(SALES!$A$5:$A$2000)-4)+(1-((SALES!$A$5:$A$2000<>"")*(COUNTIF($K$15:$K36,SALES!$A$5:$A$2000)=0)))*1000000,1))),"") | K37: =IF($J37="","",INDEX(SALES!$A$5:$A$2000,$J37))
J38: =IFERROR(IF(SUMPRODUCT(SMALL(((SALES!$A$5:$A$2000<>"")*(COUNTIF($K$15:$K37,SALES!$A$5:$A$2000)=0))*(ROW(SALES!$A$5:$A$2000)-4)+(1-((SALES!$A$5:$A$2000<>"")*(COUNTIF($K$15:$K37,SALES!$A$5:$A$2000)=0)))*1000000,1))>=1000000,"",SUMPRODUCT(SMALL(((SALES!$A$5:$A$2000<>"")*(COUNTIF($K$15:$K37,SALES!$A$5:$A$2000)=0))*(ROW(SALES!$A$5:$A$2000)-4)+(1-((SALES!$A$5:$A$2000<>"")*(COUNTIF($K$15:$K37,SALES!$A$5:$A$2000)=0)))*1000000,1))),"") | K38: =IF($J38="","",INDEX(SALES!$A$5:$A$2000,$J38))
A39: Each label shows the rate from the GST / CGST / SGST / IGST (%) columns of the order's first Sales row; each amount = rate x Subtotal. Enter only the applicable taxes (e.g. CGST+SGST, or IGST) so nothing is counted twice. | J39: =IFERROR(IF(SUMPRODUCT(SMALL(((SALES!$A$5:$A$2000<>"")*(COUNTIF($K$15:$K38,SALES!$A$5:$A$2000)=0))*(ROW(SALES!$A$5:$A$2000)-4)+(1-((SALES!$A$5:$A$2000<>"")*(COUNTIF($K$15:$K38,SALES!$A$5:$A$2000)=0)))*1000000,1))>=1000000,"",SUMPRODUCT(SMALL(((SALES!$A$5:$A$2000<>"")*(COUNTIF($K$15:$K38,SALES!$A$5:$A$2000)=0))*(ROW(SALES!$A$5:$A$2000)-4)+(1-((SALES!$A$5:$A$2000<>"")*(COUNTIF($K$15:$K38,SALES!$A$5:$A$2000)=0)))*1000000,1))),"") | K39: =IF($J39="","",INDEX(SALES!$A$5:$A$2000,$J39))
A40: Confirm rates and invoice format with Finance before issuing. Up to 15 product lines per order. Draft - review before sharing externally. | J40: =IFERROR(IF(SUMPRODUCT(SMALL(((SALES!$A$5:$A$2000<>"")*(COUNTIF($K$15:$K39,SALES!$A$5:$A$2000)=0))*(ROW(SALES!$A$5:$A$2000)-4)+(1-((SALES!$A$5:$A$2000<>"")*(COUNTIF($K$15:$K39,SALES!$A$5:$A$2000)=0)))*1000000,1))>=1000000,"",SUMPRODUCT(SMALL(((SALES!$A$5:$A$2000<>"")*(COUNTIF($K$15:$K39,SALES!$A$5:$A$2000)=0))*(ROW(SALES!$A$5:$A$2000)-4)+(1-((SALES!$A$5:$A$2000<>"")*(COUNTIF($K$15:$K39,SALES!$A$5:$A$2000)=0)))*1000000,1))),"") | K40: =IF($J40="","",INDEX(SALES!$A$5:$A$2000,$J40))
J41: =IFERROR(IF(SUMPRODUCT(SMALL(((SALES!$A$5:$A$2000<>"")*(COUNTIF($K$15:$K40,SALES!$A$5:$A$2000)=0))*(ROW(SALES!$A$5:$A$2000)-4)+(1-((SALES!$A$5:$A$2000<>"")*(COUNTIF($K$15:$K40,SALES!$A$5:$A$2000)=0)))*1000000,1))>=1000000,"",SUMPRODUCT(SMALL(((SALES!$A$5:$A$2000<>"")*(COUNTIF($K$15:$K40,SALES!$A$5:$A$2000)=0))*(ROW(SALES!$A$5:$A$2000)-4)+(1-((SALES!$A$5:$A$2000<>"")*(COUNTIF($K$15:$K40,SALES!$A$5:$A$2000)=0)))*1000000,1))),"") | K41: =IF($J41="","",INDEX(SALES!$A$5:$A$2000,$J41))
